Workbook

Sheet DOCPROPERTIES
A1: SAP_PROPOSED_FILENAME | B1: SMAS-2AGC06-0000-10546900-RevE-SL_INSTRUMENT_LIST
A2: SAP_V1_VERSION | B2: A
A3: SAP_V1_USER | B3: belluca
A4: SAP_V1_RELEASE_USER | B4: belluca
A5: SAP_V1_RELEASE_DATE | B5: 2025-03-07
A6: SAP_V2_VERSION | B6: B
A7: SAP_V2_USER | B7: laquama
A8: SAP_V2_RELEASE_USER | B8: belluca
A9: SAP_V2_RELEASE_DATE | B9: 2025-04-29
A10: SAP_V3_VERSION | B10: C
A11: SAP_V3_USER | B11: laquama
A12: SAP_V3_RELEASE_USER | B12: belluca
... A19: SAP_V5_USER | B19: laquama
A20: SAP_V5_RELEASE_USER
A21: SAP_V5_RELEASE_DATE
A22: SAP_V6_VERSION
A23: SAP_V6_USER
A24: SAP_V6_RELEASE_USER
A25: SAP_V6_RELEASE_DATE
A26: SAP_DEPARTMENT_RELEASE_USER | B26: aut
A27: SAP_DESCRIPTION | B27: INSTRUMENT LIST
A28: SAP_APPLICATION | B28: XLS:P
A29: SAP_DTYPE | B29: SLX1
A30: SAP_DOCID | B30: 2-10546900
A31: SAP_DOCTYPE | B31: HSP
A32: SAP_DOCPART | B32: 000
A33: SAP_DOCVERSION | B33: E
A34: SAP_REVLEVEL
A35: SAP_DOCTEXT_EN | B35: INSTRUMENT LIST
A36: SAP_DOCTEXT_DE | B36: INSTRUMENTENLISTE
A37: SAP_DOCTEXT_EN_1
A38: SAP_DOCTEXT_DE_1
A39: SAP_DOCTEXT_EN_2
A40: SAP_DOCTEXT_DE_2
A41: SAP_USERNAME | B41: laquama
A42: SAP_CREATION_USER | B42: laquama
A43: SAP_CREATION_DATE | B43: 2024-10-30
A44: SAP_REVIEW_DATE | B44: 2024-10-30
A45: SAP_REVIEW_USER | B45: belluca
A46: SAP_RELEASE_DATE | B46: 2024-10-30
...

Sheet Cover Sheet
B4: =INDEX(DOCPROPERTIES!B:B,MATCH("SAP_STDBEN_EN",DOCPROPERTIES!A:A,0)) -> INSTRUMENT LIST | AA4: =INDEX(DOCPROPERTIES!B:B,MATCH("SAP_POWER_HOUSE_NAME",DOCPROPERTIES!A:A,0)) -> Santa Massenza
B5: =INDEX(DOCPROPERTIES!B:B,MATCH("SAP_USER_DEFINED_DESCRIPTION",DOCPROPERTIES!A:A,0))
B6: =INDEX(DOCPROPERTIES!B:B,MATCH("SAP_CONTENT_TYPE",DOCPROPERTIES!A:A,0)) -> Signal List | AA6: Doc. ID: | AG6: =INDEX(DOCPROPERTIES!B:B,MATCH("SAP_DOCID",DOCPROPERTIES!A:A,0)) -> 2-10546900
AA7: Doc. Rev.: | AG7: =INDEX(DOCPROPERTIES!B:B,MATCH("SAP_DOCVERSION",DOCPROPERTIES!A:A,0)) -> E
F17: =INDEX(DOCPROPERTIES!B:B,MATCH("SAP_POWER_HOUSE_NAME",DOCPROPERTIES!A:A,0)) -> Santa Massenza
F18: Unit no. 4
C19: =#REF! -> #REF!
F20: =INDEX(DOCPROPERTIES!B:B,MATCH("SAP_STDBEN_EN",DOCPROPERTIES!A:A,0)) -> INSTRUMENT LIST
F21: =INDEX(DOCPROPERTIES!B:B,MATCH("SAP_USER_DEFINED_DESCRIPTION",DOCPROPERTIES!A:A,0))
F23: =INDEX(DOCPROPERTIES!B:B,MATCH("SAP_CONTENT_TYPE",DOCPROPERTIES!A:A,0)) -> Signal List
B35: Rev. | D35: Page | G35: Description | Z35: Created by | AF35: Approved by | AL35: Release Date
B36: =INDEX(DOCPROPERTIES!B:B,MATCH("SAP_V1_VERSION",DOCPROPERTIES!A:A,0)) -> A | G36: Aggiunta strumentazione supporti e correzione tag | Z36: =INDEX(DOCPROPERTIES!B:B,MATCH("SAP_V1_USER",DOCPROPERTIES!A:A,0)) -> belluca | AF36: =INDEX(DOCPROPERTIES!B:B,MATCH("SAP_V1_RELEASE_USER",DOCPROPERTIES!A:A,0)) -> belluca | AL36: =INDEX(DOCPROPERTIES!B:B,MATCH("SAP_V1_RELEASE_DATE",DOCPROPERTIES!A:A,0)) -> 2025-03-07
B37: =INDEX(DOCPROPERTIES!B:B,MATCH("SAP_V2_VERSION",DOCPROPERTIES!A:A,0)) -> B | G37: Aggiornamento generale dopo commenti HDE | Z37: =INDEX(DOCPROPERTIES!B:B,MATCH("SAP_V2_USER",DOCPROPERTIES!A:A,0)) -> laquama | AF37: =INDEX(DOCPROPERTIES!B:B,MATCH("SAP_V2_RELEASE_USER",DOCPROPERTIES!A:A,0)) -> belluca | AL37: =INDEX(DOCPROPERTIES!B:B,MATCH("SAP_V2_RELEASE_DATE",DOCPROPERTIES!A:A,0)) -> 2025-04-29
B38: =INDEX(DOCPROPERTIES!B:B,MATCH("SAP_V3_VERSION",DOCPROPERTIES!A:A,0)) -> C | G38: Aggiunta V.M. irrorazione modificati F.C. giunto | Z38: =INDEX(DOCPROPERTIES!B:B,MATCH("SAP_V3_USER",DOCPROPERTIES!A:A,0)) -> laquama | AF38: =INDEX(DOCPROPERTIES!B:B,MATCH("SAP_V3_RELEASE_USER",DOCPROPERTIES!A:A,0)) -> belluca | AL38: =INDEX(DOCPROPERTIES!B:B,MATCH("SAP_V3_RELEASE_DATE",DOCPROPERTIES!A:A,0)) -> 2025-10-03
B39: =INDEX(DOCPROPERTIES!B:B,MATCH("SAP_V4_VERSION",DOCPROPERTIES!A:A,0)) -> D | G39: Ins. marca e mod. strumentazione / Modificati segnali indicati con "D" nella colonna "Rev." | Z39: =INDEX(DOCPROPERTIES!B:B,MATCH("SAP_V4_USER",DOCPROPERTIES!A:A,0)) -> borrona | AF39: =INDEX(DOCPROPERTIES!B:B,MATCH("SAP_V4_RELEASE_USER",DOCPROPERTIES!A:A,0)) -> belluca | AL39: =INDEX(DOCPROPERTIES!B:B,MATCH("SAP_V4_RELEASE_DATE",DOCPROPERTIES!A:A,0)) -> 2025-11-17
B40: =INDEX(DOCPROPERTIES!B:B,MATCH("SAP_V5_VERSION",DOCPROPERTIES!A:A,0)) -> E | G40: Aggiunti FSW1 e FSW2 per circuito irrorazione gir. | Z40: =INDEX(DOCPROPERTIES!B:B,MATCH("SAP_V5_USER",DOCPROPERTIES!A:A,0)) -> laquama | AF40: =INDEX(DOCPROPERTIES!B:B,MATCH("SAP_V5_RELEASE_USER",DOCPROPERTIES!A:A,0)) | AL40: =INDEX(DOCPROPERTIES!B:B,MATCH("SAP_V5_RELEASE_DATE",DOCPROPERTIES!A:A,0))
B41: =INDEX(DOCPROPERTIES!B:B,MATCH("SAP_V6_VERSION",DOCPROPERTIES!A:A,0)) | Z41: =INDEX(DOCPROPERTIES!B:B,MATCH("SAP_V6_USER",DOCPROPERTIES!A:A,0)) | AF41: =INDEX(DOCPROPERTIES!B:B,MATCH("SAP_V6_RELEASE_USER",DOCPROPERTIES!A:A,0)) | AL41: =INDEX(DOCPROPERTIES!B:B,MATCH("SAP_V6_RELEASE_DATE",DOCPROPERTIES!A:A,0))
B44: Created by | I44: Date | P44: Checked by | W44: Date | AD44: Approved by | AK44: Date
B45: =INDEX(DOCPROPERTIES!B:B,MATCH("SAP_CREATION_USER",DOCPROPERTIES!A:A,0)) -> laquama | I45: =INDEX(DOCPROPERTIES!B:B,MATCH("SAP_CREATION_DATE",DOCPROPERTIES!A:A,0)) -> 2024-10-30 | P45: =INDEX(DOCPROPERTIES!B:B,MATCH("SAP_REVIEW_USER",DOCPROPERTIES!A:A,0)) -> belluca | W45: =INDEX(DOCPROPERTIES!B:B,MATCH("SAP_REVIEW_DATE",DOCPROPERTIES!A:A,0)) -> 2024-10-30 | AD45: =INDEX(DOCPROPERTIES!B:B,MATCH("SAP_RELEASE_USER",DOCPROPERTIES!A:A,0)) -> belluca | AK45: =INDEX(DOCPROPERTIES!B:B,MATCH("SAP_RELEASE_DATE",DOCPROPERTIES!A:A,0)) -> 2024-10-30

Sheet IO LIST
A1: SIGLA | B1: DESCRIZIONE | C1: DESCRIZIONE PER LISTA IO (da HDE) | D1: NOTE HDE | E1: COSTRUTTORE | F1: MODELLO | G1: WIRABLE SOCKET | H1: CONNECTOR CABLES WITH SOCKET | I1: UBICAZIONE | J1: TIPO | K1: CONTATTO | L1: SEGNALE | M1: CAR. ELETT. | N1: CASS. | O1: MORS. | P1: FORNITORE | Q1: REV. | R1: NOTE | S1: INFO
A2: 88PQ | B2: Motore pompa PQ | C2: AVVIAMENTO POMPA CHIUSURA VALVOLA DI RITEGNO | E2: Sovem | F2: M-4kW 4P 230/400-50 B5 IE3 | I2: Centralina oleodinamica bassa pressione P4 | J2: DO | M2: 400Vca 4KW | P2: VOITH | R2: cablaggio fino a strumento da realizzare in impianto | S2: Elenco segnali in revisione E redatto su schema idraulico n. 10527153 Revisione G
A3: ED1.1 (65S.1) | B3: Elettrovalvola messa in sicurezza turbina 1 | C3: SOD A4 - ECCITAZIONE ED1.1 (65S.1) | E3: Bosch Rexroth | F3: 3SED06 CK XX/350 CG125N9K4 | I3: Centralina oleodinamica alta pressione A4 | J3: DO | M3: +125Vcc 30W | N3: JB00 | O3: X1 | P3: VOITH
A4: ED1.2 (65S.2) | B4: Elettrovalvola messa in sicurezza turbina 2 | C4: SOD A4 - ECCITAZIONE ED1.2 (65S.2) | E4: Bosch Rexroth | F4: 3SED06 CK XX/350 CG125N9K4 | I4: Centralina oleodinamica alta pressione A4 | J4: DO | M4: +125Vcc 30W | N4: JB00 | O4: X1 | P4: VOITH
A5: ED101.1 | B5: Elettrovalvola comando attivazione controgetto 1 | C5: APERTURA CONTROGETTO 1 | E5: Bosch Rexroth | F5: 3SED06 CK XX/350 CG125N9K4 | I5: Centralina oleodinamica alta pressione A4 | J5: DO | M5: +125Vcc 30W | N5: JB00 | O5: X1 | P5: VOITH
A6: ED101.2 | B6: Elettrovalvola comando attivazione controgetto 2 | C6: APERTURA CONTROGETTO 2 | E6: Bosch Rexroth | F6: 3SED06 CK XX/350 CG125N9K4 | I6: Centralina oleodinamica alta pressione A4 | J6: DO | M6: +125Vcc 30W | N6: JB00 | O6: X1 | P6: VOITH
A7: ED2/1 | B7: Elettrovalvola comando rotazione valvola rotativa V41 - sinistra | C7: APERTURA ROTATIVA V41 | E7: Bosch Rexroth | F7: 3SED06 CK XX/350 CG125N9K4 | I7: Quadro valvola rotativa - lato V41 | J7: DO | M7: +125Vcc 30W | N7: JB06 | O7: X1 | P7: VOITH
A8: ED2/2 | B8: Elettrovalvola comando rotazione valvola rotativa V42 - destra | C8: APERTURA ROTATIVA V42 | E8: Bosch Rexroth | F8: 3SED06 CK XX/350 CG125N9K4 | I8: Quadro valvola rotativa - lato V42 | J8: DO | M8: +125Vcc 30W | N8: JB06 | O8: X3 | P8: VOITH
A9: ED3.A4 (S20Q) | B9: Elettrovalvola bistabile comando VRP3.A4 - centralina alta pressione turbina | C9: SOD A4 - APERTURA VRP3.A4 (20Q.A4) | E9: Bosch Rexroth | F9: 4WE06 D/OF XX/EG110 N9K4 | I9: Centralina oleodinamica alta pressione A4 | J9: DO | M9: +110Vcc 30W + 30W | N9: JB00 | O9: X1 | P9: VOITH
A10: ED3.P4 (S20Q.P4) | B10: Elettrovalvola bistabile comando VRP3.P4 - centralina bassa pressione pompa | C10: SOD P4 - APERTURA VRP3.P4 (20Q.P4) | E10: Bosch Rexroth | F10: 4WE06 D/OF XX/EG110 N9K4 | I10: Centralina oleodinamica bassa pressione P4 | J10: DO | M10: +110Vcc 30W + 30W | N10: JB07 | O10: X1 | P10: VOITH
A11: ED9/1 | B11: Elettrovalvola comando by-pass valvola rotativa V41 - sinistra (FUTURO) | C11: APERTURA BYPASS V41 (PREDISPOSIZIONE) | E11: Bosch Rexroth | F11: 3SED10 CK XX/350 CG125N9K4 | I11: Quadro valvola rotativa - lato V41 | J11: DO | M11: +125Vcc 30W | N11: JB06 | O11: X1 | P11: VOITH
A12: ED9/2 | B12: Elettrovalvola comando by-pass valvola rotativa V42 - destra (FUTURO) | C12: APERTURA BYPASS V42 (PREDISPOSIZIONE) | E12: Bosch Rexroth | F12: 3SED10 CK XX/350 CG125N9K4 | I12: Quadro valvola rotativa - lato V42 | J12: DO | M12: +125Vcc 30W | N12: JB06 | O12: X3 | P12: VOITH
A13: EDGI | B13: Elettrovalvola bistabile comando giunto | C13: INSERZIONE GIUNTO | E13: ARGO-HYTOS | F13: RPE3-062J15/11000E1S1 | I13: Centralina oleodinamica bassa pressione P4 | J13: DO | M13: +110Vcc 30W + 30W | N13: JB07 | O13: X1 | P13: VOITH
A14: EDGI.ROT | B14: Elettrovalvola mancanto innesto giunto - rotazione | C14: ECCITAZIONE EV DI MANCATO INNESTO GIUNTO | E14: Bosch Rexroth | F14: 3SED06 CK XX/350 CG125N9K4 | I14: Centralina oleodinamica bassa pressione P4 | J14: DO | M14: +125Vcc 30W | N14: JB07 | O14: X1 | P14: VOITH
A15: EDVSO.A4 | B15: Elettrovalvola messa a scarico pompe olio - centralina alta pressione turbina | C15: SOD A4 - ECCITAZIONE EV DI MESSA A SCARICO OLIO | E15: Bosch Rexroth | F15: 4WE06 Y 6X/EG110 N9K4 | I15: Centralina oleodinamica alta pressione A4 | J15: DO | M15: +110Vcc 30W | N15: JB00 | O15: X1 | P15: VOITH | Q15: D: corretta alimentazione
A16: EDVSO.P4 | B16: Elettrovalvola messa a scarico pompe olio - centralina bassa pressione pompa | C16: SOD P4 - ECCITAZIONE EV DI MESSA A SCARICO OLIO | E16: Bosch Rexroth | F16: 4WE06 Y 6X/EG110 N9K4 | I16: Centralina oleodinamica bassa pressione P4 | J16: DO | M16: +110Vcc 30W | N16: JB07 | O16: X1 | P16: VOITH | Q16: D: corretta alimentazione
A17: ER.A4 | B17: Scaldiglia riscaldamento olio serbatoio centralina centralina alta pressione turbina | C17: SOD A4 - AVVIAMENTO RISCALDAMENTO OLIO | E17: Resistor | F17: 1500W 400V/3/50 L=600 2.1/2"G | I17: Centralina oleodinamica alta pressione A4 | J17: DO | M17: 400Vca 1,5KW | P17: VOITH | R17: cablaggio fino a strumento da realizzare in impianto
A18: ER.P4 | B18: Scaldiglia riscaldamento olio serbatoio centralina centralina bassa pressione pompa | C18: SOD P4 - AVVIAMENTO RISCALDAMENTO OLIO | E18: Resistor | F18: 1500W 400V/3/50 L=600 2.1/2"G | I18: Centralina oleodinamica bassa pressione P4 | J18: DO | M18: 400Vca 1,5KW | P18: VOITH | R18: cablaggio fino a strumento da realizzare in impianto
A19: ST1 | B19: Captatore di velocità - rilievo velocità turbina | C19: VELOCITÀ 1 PER AUTOMAZIONE | E19: BRAUN | F19: A5S0DS0M1815B74 | G19: plug-in angled metal connector M18x1,5 | H19: plug-in angled metal connector M18x1,5 | I19: SSG | J19: DI | K19: IMPULSIVO | M19: +24Vcc | N19: DIRETTO | P19: VOITH | R19: cablaggio fino a strumento da realizzare in impianto
A20: ST2 | B20: Captatore di velocità - rilievo velocità turbina | C20: VELOCITÀ 2 PER AUTOMAZIONE | E20: BRAUN | F20: A5S0DS0M1815B74 | G20: plug-in angled metal connector M18x1,5 | H20: plug-in angled metal connector M18x1,5 | I20: SSG | J20: DI | K20: IMPULSIVO | M20: +24Vcc | N20: DIRETTO | P20: VOITH | R20: cablaggio fino a strumento da realizzare in impianto
A21: FSW.A4 | B21: Flussostato acqua raffreddamento - presenza circolazione acqua - centralina alta pressione turbina | C21: SOD A4 - PRESENZA CIRCOLAZ. ACQUA RAFF. | E21: IFM | F21: SBG234 | I21: Centralina oleodinamica alta pressione A4 | J21: DI | K21: PNP | M21: +24Vcc | N21: JB00 | O21: X1 | P21: VOITH
A22: FSW.P4 | B22: Flussostato acqua raffreddamento - presenza circolazione acqua - centralina bassa pressione pompa | C22: SOD P4 - PRESENZA CIRCOLAZ. ACQUA RAFF. | E22: IFM | F22: SBG234 | I22: Centralina oleodinamica bassa pressione P4 | J22: DI | K22: PNP | M22: +24Vcc | N22: JB07 | O22: X1 | P22: VOITH
A23: ST3 | B23: Captatore di velocità - rilievo velocità turbina | C23: VELOCITÀ 1 PER REGOLATORE DI VELOCITÀ | E23: BRAUN | F23: A5S0DS0M1815B74 | G23: plug-in angled metal connector M18x1,5 | H23: plug-in angled metal connector M18x1,5 | I23: SSG | J23: DI | K23: IMPULSIVO | M23: +24Vcc | N23: DIRETTO | P23: VOITH | R23: cablaggio fino a strumento da realizzare in impianto
A24: ST4 | B24: Captatore di velocità - rilievo velocità turbina | C24: VELOCITÀ 2 PER REGOLATORE DI VELOCITÀ | E24: BRAUN | F24: A5S0DS0M1815B74 | G24: plug-in angled metal connector M18x1,5 | H24: plug-in angled metal connector M18x1,5 | I24: SSG | J24: DI | K24: IMPULSIVO | M24: +24Vcc | N24: DIRETTO | P24: VOITH | R24: cablaggio fino a strumento da realizzare in impianto
A25: LS1.HH.A4 | B25: Livellostato livello olio serbatoio centralina - livello olio massimo - centralina alta pressione turbina | C25: SOD A4 - MAX LIVELLO OLIO CENTRALINA | E25: F.lli Giacomello | F25: RL/G1-F3-S2 L=100mm | I25: Centralina oleodinamica alta pressione A4 | J25: DI | K25: SPDT | L25: NO | M25: Contatto pulito | N25: JB00 | O25: X1 | P25: VOITH
A26: LS1.LL.A4 | B26: Livellostato livello olio serbatoio centralina - livello olio minimo - centralina alta pressione turbina | C26: SOD A4 - MIN LIVELLO OLIO CENTRALINA | E26: F.lli Giacomello | F26: RL/G1-F3-S2 L=400mm | I26: Centralina oleodinamica alta pressione A4 | J26: DI | K26: SPDT | L26: NO | M26: Contatto pulito | N26: JB00 | O26: X1 | P26: VOITH
A27: LS1_HH.P4 | B27: Livellostato livello olio serbatoio centralina - livello olio massimo - centralina bassa pressione pompa | C27: SOD P4 - MAX LIVELLO OLIO CENTRALINA | E27: F.lli Giacomello | F27: RL/G1-F3-S2 L=250mm | I27: Centralina oleodinamica bassa pressione P4 | J27: DI | K27: SPDT | L27: NO | M27: Contatto pulito | N27: JB07 | O27: X1 | P27: VOITH
A28: LS1_LL.P4 | B28: Livellostato livello olio serbatoio centralina - livello olio minimo - centralina bassa pressione pompa | C28: SOD P4 - MIN LIVELLO OLIO CENTRALINA | E28: F.lli Giacomello | F28: RL/G1-F3-S2 L=550mm | I28: Centralina oleodinamica bassa pressione P4 | J28: DI | K28: SPDT | L28: NO | M28: Contatto pulito | N28: JB00 | O28: X1 | P28: VOITH
A29: ZTS.V4 | B29: Trasduttore di posizione valvola rotativa aspirazione pompa | C29: POSIZIONE SERVOMOTORE DI ROTAZIONE V4 | E29: Camille bauer | F29: WT707 | G29: metalna kabelska uvodnica | H29: metalna kabelska uvodnica | I29: Valvola rotativa aspirazione pompa V4 | J29: AI | L29: 4-20mA 0÷100% | M29: +24Vcc | P29: VOITH | R29: cablaggio fino a strumento da realizzare in impianto
A30: ZTS.V40 | B30: Trasduttore di posizione valvola rotativa mandata pompa | C30: POSIZIONE SERVOMOTORE DI ROTAZIONE V40 | E30: Camille bauer | F30: WT707 | G30: metalna kabelska uvodnica | H30: metalna kabelska uvodnica | I30: Valvola rotativa mandata pompa V40 | J30: AI | L30: 4-20mA 0÷100% | M30: +24Vcc | P30: VOITH | R30: cablaggio fino a strumento da realizzare in impianto
A31: LQ.max | B31: Livellostato - Massimo livello Serbatoio di compenso sopraelevato | C31: MASSIMO LIVELLO OLIO SERBATOIO DI COMPENSAZIONE | E31: F.lli Giacomello | F31: RL/G1-F3-S2 L=240mm | I31: Serbatoio di compenso sopraelevato - valvola ritegno | J31: DI | K31: SPDT | L31: NO | M31: Contatto pulito | P31: VOITH | R31: cablaggio fino a strumento da realizzare in impianto
A32: LQ.min | B32: Livellostato - Minimo livello Serbatoio di compenso sopraelevato | C32: MINIMO LIVELLO OLIO SERBATOIO DI COMPENSAZIONE | E32: F.lli Giacomello | F32: RL/G1-F3-S2 L=280mm | I32: Serbatoio di compenso sopraelevato - valvola ritegno | J32: DI | K32: SPDT | L32: NO | M32: Contatto pulito | P32: VOITH | R32: cablaggio fino a strumento da realizzare in impianto
A33: LS3.A4 | B33: Livellostato livello olio cassone perdite centralina_SO2 - presenza perdite olio - centralina alta pressione turbina | C33: SOD A4 - PRESENZA PERDITE OLIO CENTRALINA | E33: F.lli Giacomello | F33: RL/G1-F3-S2 L=100mm | I33: Centralina oleodinamica alta pressione A4 | J33: DI | K33: SPDT | L33: NO | M33: Contatto pulito | P33: VOITH
A34: LS3.P4 | B34: Livellostato livello olio cassone perdite centralina_SO2 - presenza perdite olio - centralina bassa pressione pompa | C34: SOD P4 - PRESENZA PERDITE OLIO CENTRALINA | E34: F.lli Giacomello | F34: RL/G1-F3-S2 L=100mm | I34: Centralina oleodinamica bassa pressione P4 | J34: DI | K34: SPDT | L34: NO | M34: Contatto pulito | P34: VOITH
A35: LS6.P4 | B35: Livellostato - vasca di raccolta perdite giunto rotante innesto giunto a denti - presenza perdita olio | C35: PRESENZA PERDITE OLIO GIUNTO ROTANTE INNESTO GIUNTO A DENTI | E35: F.lli Giacomello | F35: IEG - INOX- FD 3061 HC 03 | G35: ugrađen kabel 30 cm | H35: ugrađen kabel 30 cm | I35: Vasca di raccolta perdite - Giunto rotante innesto giunto a denti | J35: DI | K35: SPDT | L35: NO | M35: Contatto pulito | P35: ESISTENTE | Q35: D | R35: cablaggio fino a strumento da realizzare in impianto
A36: PDS15 | B36: Pressostato differenziale - intasamento filtro acqua FW15 - acqua manovra rotative pompa | C36: INTASAMENTO FILTRO ACQUA ROTATIVE V4/V40 | E36: IFH | F36: Integrato nel filtro | I36: Valvola rotativa mandata pompa V40 | J36: DI | K36: SPDT | L36: NO | M36: Contatto pulito | P36: VOITH | R36: cablaggio fino a strumento da realizzare in impianto
A37: LS4/1 | B37: Livellostato - vasca di raccolta perdite introduttore supreriore turbina 1 / olio misto acqua - presenza perdita | C37: PRESENZA PERDITE OLIO SPINA SUPERIORE TURBINA 1 | E37: F.lli Giacomello | F37: RL/G1-F3-S2 L=200mm | I37: Vasca di raccolta perdite - Turbina 1 sinistra | J37: DI | K37: SPDT | L37: NO | M37: Contatto pulito | N37: JB04 | O37: X1 | P37: VOITH
A38: LS4/2 | B38: Livellostato - vasca di raccolta perdite introduttore inferiore turbina 1 / olio misto acqua - presenza perdita | C38: PRESENZA PERDITE OLIO SPINA INFERIORE TURBINA 1 | E38: F.lli Giacomello | F38: RL/G1-F3-S2 L=200mm | I38: Vasca di raccolta perdite - Turbina 1 sinistra | J38: DI | K38: SPDT | L38: NO | M38: Contatto pulito | N38: JB04 | O38: X1 | P38: VOITH
A39: LS5/1 | B39: Livellostato - vasca di raccolta perdite introduttore supreriore turbina 2 / olio misto acqua - presenza perdita | C39: PRESENZA PERDITE OLIO SPINA SUP TURB 2 | E39: F.lli Giacomello | F39: RL/G1-F3-S2 L=200mm | I39: Vasca di raccolta perdite - Turbina 2 destra | J39: DI | K39: SPDT | L39: NO | M39: Contatto pulito | N39: JB04 | O39: X1 | P39: VOITH
A40: LS5/2 | B40: Livellostato - vasca di raccolta perdite introduttore inferiore turbina 2 / olio misto acqua - presenza perdita | C40: PRESENZA PERDITE OLIO SPINA INF TURB 2 | E40: F.lli Giacomello | F40: RL/G1-F3-S2 L=200mm | I40: Vasca di raccolta perdite - Turbina 2 destra | J40: DI | K40: SPDT | L40: NO | M40: Contatto pulito | N40: JB04 | O40: X1 | P40: VOITH
...
