Workbook

Sheet Ažuriranja MCCa
A1: Rd.br. | B1: Ormar | C1: Datum | D1: Opis | E1: Status | F1: Napomena | G1: Oprema
D2: 1mj.26. NAPOMENE
D5: 8mj.25. NAPOMENE
A6: 1. | B6: MCC Normal 4LKD002AR | C6: 20.08.2025. | D6: Izvod "FAST FILING PUMP" - sa 22kW na 11kW - potrebno postaviti novu motorku i sklopnik | E6: - NE UCRTAVATI JOŠ doći će do promjene | F6: provjeri je li naručena oprema | G6: GV2P22+GVAE11+GVAD0110 LC1D25P7+LADN31+LAD4RCU
A7: 2. | B7: MCC Normal 4LKD003AR | C7: 11.08.2025. | D7: Novi izvod: CHAIN CONVEYOR FOR BOTTOM ASH - 4 FDR 009 MO - 4KW (dvosmjerni) | E7: - ucrtano u EPLAN (na zadnje mjesto) - naručiti opremu | F7: provjeri je li naručena oprema
A8: 3. | B8: MCC Emergency 4LKF002AR | C8: 11.08.2025. | D8: Novi izvod: "Grate expansion tank system" (nemamo tehničke podatke) SYSTÈME DE RÉSERVOIR D'EXPANSION À GRILLE | E8: - ucrtano u EPLAN (na zadnje mjesto) - naručiti opremu | F8: provjeri je li naručena oprema | G8: SE.18727 + SE.19072 SOC.47506030 + SOC.47290590
A9: 4. | B9: MCC Emergency 4LKF002AR | C9: 11.08.2025. | D9: Izvod: "EXPANSION TANK SYSTEM" - prebačen na 10kW | E9: - ucrtano u EPLAN
A10: 5. | B10: MCC - svi | C10: 20.08.2025. | D10: Potrebno je sve holdere za oznake tipkala prebaciti iz ZBZ32 na ZBZ33 (8x27 -> 18x27) | E10: - potrebno ucrtati u Eplan (nekada ako)
D14: Naknadno potrebno napraviti na terenu
A15: Rd.br. | B15: Ormar | C15: DT | D15: Stari part | E15: Novi part | F15: Napomena | G15: Napomena
B16: 4LKF002AR | C16: Q 093 04 | D16: izvod pretpostavljen 32A | E16: SE.18727 + SE.19072 SOC.47506030 + SOC.47290590
D19: promjena 07.01.2026. -> uvršteno u listu potrošača
A20: Rd.br. | B20: Ormar | C20: DT | D20: Stari part | E20: Novi part | F20: Napomena | G20: Pozicija potrošača | H20: Oprema | I20: Oprema - sklopnik | J20: STATUS
B21: 4LKD001AR | D21: FAST FILING PUMP - 11kW - na frekventni mora ići | E21: obavezno na VFD | G21: prebaciti u MCC Emergency na SPARE poziciju | H21: C10F3TM050 + LV429515 + LV429515 | I21: SIE.6SL3220-3YE26-0AF0 | J21: Dodati postojeći 11kW VFD u MCC Emergency
B22: 4LKD007AR - VFD | C22: 4 SEO 209 PO | D22: [4 SEO 209 PO] WASTE WATER PUMP 1 - neutralizacijska | E22: makni VFD -> postavi na sklopnik 3kW | F22: OLD - 11kW frekventni | G22: MCC Normal (novi ormar) | H22: GV2P14 GVAE11 (NC+NO) GVAD0110 (NC fault + NO) | I22: LC1D12P7 (1NO+1NC) LADN31 (3NO+1NC) LAD4RCU (RC) | J22: DOL
B23: 4LKD007AR - VFD | C23: 4 SEO 213 PO | D23: [4 SEO 213 PO] WASTE WATER PUMP 2- neutralizacijska | E23: makni VFD -> postavi na sklopnik 3kW | F23: OLD - 11kW frekventni | G23: MCC Normal (novi ormar) | H23: GV2P14 GVAE11 (NC+NO) GVAD0110 (NC fault + NO) | I23: LC1D12P7 (1NO+1NC) LADN31 (3NO+1NC) LAD4RCU (RC) | J23: DOL
B24: 4LKD007AR - VFD | C24: 4 SEO 264 PO | D24: [4 SEO 264 PO] WASTE WATER BOTTOM ASH PIT DISCHARG PUMP 1 - teški metal | E24: makni VFD -> postavi na sklopnik | F24: OLD - 5,5kW frekventni | G24: MCC Normal (novi ormar) | H24: GV2P16 GVAE11 (NC+NO) GVAD0110 (NC fault + NO) | I24: LC1D12P7 (1NO+1NC) LADN31 (3NO+1NC) LAD4RCU (RC) | J24: DOL
B25: 4LKD007AR - VFD | C25: 4 SEO 269 PO | D25: [4 SEO 269 PO] WASTE WATER BOTTOM ASH PIT DISCHARG PUMP 2 - teški metal | E25: makni VFD -> postavi na sklopnik | F25: OLD - 5,5kW frekventni | G25: MCC Normal (novi ormar) | H25: GV2P16 GVAE11 (NC+NO) GVAD0110 (NC fault + NO) | I25: LC1D12P7 (1NO+1NC) LADN31 (3NO+1NC) LAD4RCU (RC) | J25: DOL
A27: ATEP | B27: 4LKF003AR | C27: 4 CTE 063 PO | D27: [4 CTE 063 PO] COOLING WATER PUMP 1 | E27: prebaciti na VFD 5,5kW (gore izbačene) | F27: po Zvoni: ostavi di je | G27: prebaci u MCC emergency poziciju 5.5 kW starog potrošača
A28: ATEP | B28: 4LKF004AR | C28: 4 CTE 064 PO | D28: [4 CTE 064 PO] COOLING WATER PUMP 2 | E28: prebaciti na VFD 5,5kW (gore izbačene) | F28: po Zvoni: ostavi di je | G28: prebaci u MCC emergency poziciju 5.5 kW starog potrošača
A31: SFA | B31: 4LKF005AR - VFD | C31: 4 CRE 189 MO 4CRF188PO | D31: [4 CRE 189 MO] COOLING WATER PUMP 1 | E31: obavezno na VFD | F31: 37kW - postojeće
A32: SFA | B32: 4LKF005AR - VFD | C32: 4 CRE 196 MO 4CRF195PO | D32: [4 CRE 196 MO] COOLING WATER PUMP 2 | E32: obavezno na VFD | F32: 37kW - postojeće

Sheet Boiler MCC distribution
A1: Napomena | B1: Boiler MCC 4LKD001AR | E1: BOILER/LOW VOLTAGE CABINET BOILER (NORMAL) | F1: CHAUDIÈRE/ARMOIRE BASSE TENSION CHAUDIÈRE (NORMALE) | M1: spare 25% -> postavljeno 30% | P1: 25kA! | Q1: 36kA | S1: prema tablici | AC1: prema tablici
B2: Oznaka EPLAN | C2: KKS OLD | D2: KKS prekidača | E2: KKS NEW | F2: KKS NEW - prijevod | G2: PID | H2: 1Ph/3Ph | I2: V | J2: kW | K2: EPLAN kW | L2: kA | M2: Struja motora [A] | N2: Simultaneity factor in maximal normal mode [%] | O2: Struja prekidača s faktorom [A] | P2: Dovodni prekidač/rastavljač SIEMENS | Q2: Dovodni prekidač/rastavljač SCHNEIDER | R2: Reverzibilni | S2: Motorna zaštita Siemens | T2: Motorna zaštita A Siemens | U2: Motorna zaštita AUX Siemens | V2: Sklopnik minimum 12A Siemens | W2: Sklopnik AUX + RC element Siemens | X2: Soft starter SIEMENS | Y2: Soft starter SCHNIDER | Z2: Frekventni | AA2: Motorna zaštita Schneider | AB2: Motorna zaštita A Schneider | AC2: Sklopnik minimum 12A Schneider | AD2: 1F Strujni trafo ampermetar | AE2: Mjerni strujni trafo za 3F el. Measurement - Socomec | AF2: Dozemni spoj - Socomec | AG2: Mjerni strujni trafo za 3F el. Measurement - Siemens | AH2: Dozemni spoj - Siemens | AI2: Prekidač za 230VAC | AJ2: Prekidač za 48VAC | AK2: RELEJ 48VAC minimum 6A | AL2: RELEJ 230VAC minimum 6A | AM2: Safety relay | AN2: Tip kabela | AO2: Strujno opterećenje kabela | AP2: vanjski promjer kabela | AQ2: Rastavna sklopka | AR2: Proizvođač motora | AS2: Klematura | AT2: Napomena
B3: ORMAR 1 2100+200x1000x600 | C3: DOVOD | D3: =4LKD001AR+4LKD001AR | M3: =SUM(M9,M21,M28,M35,M42,M49) -> 213.291 | O3: =SUM(O9,O21,O28,O35,O42,O49) -> 163.8832 | P3: 3KD3632-0NE10-0(200A) SIE.3KD9103-5 (AUX) 3KD9204-7 (cable cover) | Q3: C25B3TM250 + LV432597T + 2x LV432593
Q4: INS 250 - 31106 29450 (NO/NC) 2xLV429518 (cover) | AQ4: LV481453 -> ispod ide odvodnik prenapona
D5: Predikač prije odvodnika - | AE5: 3x 48290573
D6: Odvodnik prenapona - 5SD7473-1
D7: Nadzor faza - 3UG5514-1BR20
D8: Okretno polje -
B9: ORMAR 2 2100+200x1000x600 | D9: =4LKD001AR+4LKD002AR | J9: =SUM(J10:J14) -> 23 | K9: =SUM(K10:K14) -> 23 | M9: =SUM(M10:M20)+(SUM(M10:M20)*0.3) -> 53.547 | O9: =SUM(O10:O20)+(SUM(O10:O20)*0.3) -> 22.3626 | P9: 3VA1063-3ED32-0AA0 - 63A 3VA9988-0AA12 AUX 1CO 3VA9157-0EK11 Rotary 3VA9152-0WA00 phase barrier -> 2 kom 3VA9111-0WD30 mala zaštita odozgora 3VA9113-0JF60 distri odozdola i izolacija | Q9: C10F3TM100 - 100A 36kA +29450 (1CO) +LV429337T (rotary) +LVS04033 (distriblock dole) +LV429517 (duga zaštita)
B10: -F11 - SPARE | C10: FAST FILING PUMP | D10: SPARE BIO JE: [4 SDX 001 PO] FAST FILING PUMP | AQ10: LV481603 + GS1AH103 + ZBE101 + GS1AM110
B11: -F12 | C11: CLOSED CHAIN CONVEYOR 1 | D11: 4 FES 004 MO | E11: [4 FES 004 MO] MAIN CLOSED CHAIN CONVEYOR | F11: CONVOYEUR PRINCIPAL À CHAÎNE FERMÉ | G11: Ash system | H11: 3Ph | I11: 400 | J11: 1.5 | K11: 1.5 | M11: =ROUND(J11/(1.73*0.4),2) -> 2.17 | N11: 80 | O11: =M11*(N11/100) -> 1.736 | R11: ☑ | S11: 3RV2021-1FA10 | T11: 3.5 - 5 A | U11: SIE.3RV2901-1E 3RV2901-1A | V11: 3RT2015-1AP02 (1NC) 3RT2015-1AP02 (1NC) 3RA2913-2AA1 (interlock) | W11: 3RT2916-1CD00 (RC) 3RT2936-1CD00 (RC) 3RH2911-1HA31 (aux) 3RH2911-1HA31 (aux) | AA11: GV2P08 GVAE11 (NC+NO) GVAD0110 (NC fault + NO) | AB11: 2.5 - 4 A | AC11: 2x LC1D12P7 (1NO+1NC) 2x LADN31 (3NO+1NC) 2x LAD4RCU (RC) LAD9R1V (intelock blokada) | AF11: 47506015 | AH11: 3UF7011-1AU00-1 - base unit 3UF7510-1AA00-0 - ground fault 3UL2302-1A - trafo 35mm | AI11: A9F74202 | AJ11: A9F74202 | AK11: RXM4AB2E7 RXZE2S114M RXM021BN | AL11: LZS:PT5A5T30 LZS:PTMU0730 | AM11: XPSBAC34AP | AN11: U1000R2V 4G2,5 | AO11: 32 | AP11: 11.1 | AQ11: LV481603 + GS1AH103 + ZBE101 + GS1AM110 | AR11: NORD
B12: -F13 | C12: Screw conveyor | D12: 4 FES 002 MO | E12: [4 FES 002 MO] REVERSING SCREW CONVEYOR BELOW EX. ECO | F12: CONVOYEUR À VIS SOUS L'ÉCO | G12: Ash system | H12: 3Ph | I12: 400 | J12: 1.5 | K12: 1.5 | M12: =ROUND(J12/(1.73*0.4),2) -> 2.17 | N12: 80 | O12: =M12*(N12/100) -> 1.736 | R12: ☑ | S12: 3RV2021-1FA10 | T12: 3.5 - 5 A | U12: SIE.3RV2901-1E 3RV2901-1A | V12: 3RT2015-1AP02 (1NC) 3RT2015-1AP02 (1NC) 3RA2913-2AA1 (interlock) | W12: 3RT2916-1CD00 (RC) 3RT2936-1CD00 (RC) 3RH2911-1HA31 (aux) 3RH2911-1HA31 (aux) | AA12: GV2P08 GVAE11 (NC+NO) GVAD0110 (NC fault + NO) | AB12: 2.5 - 4 A | AC12: 2x LC1D12P7 (1NO+1NC) 2x LADN31 (3NO+1NC) 2x LAD4RCU (RC) LAD9R1V (intelock blokada) | AF12: 47506015 | AH12: 3UF7011-1AU00-1 - base unit 3UF7510-1AA00-0 - ground fault 3UL2302-1A - trafo 35mm | AI12: A9F74202 | AJ12: A9F74202 | AK12: RXM4AB2E7 RXZE2S114M RXM021BN | AL12: LZS:PT5A5T30 LZS:PTMU0730 | AM12: XPSBAC34AP | AN12: U1000R2V 4G2,5 | AO12: 32 | AP12: 11.1 | AQ12: LV481603 + GS1AH103 + ZBE101 + GS1AM110 | AR12: NORD
B13: -F14 | C13: SPARE (prazni prostor) | D13: 4FGO-CR-101 | E13: BURNER SYSTEM | F13: SYSTEME DE BRÛLEUR | H13: 3Ph | I13: 400 | J13: 20 | K13: 20 | M13: =ROUND(J13/(1.73*0.4),2) -> 28.9 | N13: 20 | O13: =M13*(N13/100) -> 5.78 | P13: C10F3TM032 - 32A +29450 (1CO) +LV429337T (rotary) +2x LV429517 (duga zaštita) | Q13: NG125 - 18727 - 32A +19072 (1CO) | AF13: 47506015 | AN13: U1000R2V 4G6 | AP13: 14.3
B14: -F15 | C14: SPARE (prazni prostor) | D14: 4 FES 005 MO | E14: [4 FES 005 MO] OVERBAND MAGNETIC SEPARATOR | F14: SEPARATEUR MAGNETIQUE | H14: 3Ph | I14: 400 | P14: C10B3TM016 - 16A +29450 (1CO) +LV429337T (rotary) +2x LV429517 (duga zaštita) | Q14: NG125 - 18724 - 16A +19072 (1CO) | AF14: 47506015 | AN14: U1000R2V 4G2,5 | AP14: 11.1 | AR14: NORD
B15: -F16 | D15: 4 FDR 005 BJ | E15: COOLING OIL PUMP AND FAN MOTOR | F15: POMPE À HUILE DE REFROIDISSEMENT ET MOTEUR DE VENTILATEUR | H15: 3Ph | I15: 400 | J15: 1.5 | K15: 1.5 | M15: =ROUND(J15/(1.73*0.4),2) -> 2.17 | N15: 100 | O15: =M15*(N15/100) -> 2.17 | P15: C10B3TM016 - 16A +29450 (1CO) +LV429337T (rotary) +2x LV429517 (duga zaštita) | Q15: NG125 - 18724 - 16A +19072 (1CO) | AA15: Možda 10.04.2026. GV2P08 GVAE11 (NC+NO) GVAD0110 (NC fault + NO) | AB15: 2.5 - 4 A | AC15: Možda 10.04.2026. LC1D12P7 (1NO+1NC) LADN31 (3NO+1NC) LAD4RCU (RC) | AF15: 47506015 | AN15: U1000R2V 4G2,5 | AP15: 11.1
B16: -F17 | D16: 4 SAR 200 BC | E16: PNEUMATIC RAPPING SYSTEM | F16: SYSTÈME DE RAPPEL PNEUMATIQUE | H16: 3Ph | I16: 400 | P16: C10B3TM016 - 16A +29450 (1CO) +LV429337T (rotary) +2x LV429517 (duga zaštita) | Q16: NG125 - 18724 - 16A +19072 (1CO) | AF16: 47506015 | AN16: U1000R2V 4G2,5 | AP16: 11.1
B17: -F18 | D17: 4 FES 100 BC | E17: WATER SPRAYING SYSTEM | F17: SYSTÈME DE PULVÉRISATION D'EAU | H17: 3Ph | I17: 400 | J17: 4 | K17: UBACITI U SHEME i naručiti opremu | M17: =ROUND(J17/(1.73*0.4),2) -> 5.78 | N17: 100 | O17: =M17*(N17/100) -> 5.78 | P17: C10B3TM016 - 16A +29450 (1CO) +LV429337T (rotary) +2x LV429517 (duga zaštita) | Q17: NG125 - 18724 - 16A +19072 (1CO) | AF17: 47506015 | AN17: U1000R2V 4G2,5 | AP17: 11.1
B18: -F19 | E18: SPARE (prazni prostor za izvod, samo prekidač)
B19: -F19.1 | E19: SPARE (prazni prostor za izvod, samo prekidač)
B20: -F19.2 | E20: SPARE (prazni prostor za izvod, samo prekidač)
B21: ORMAR 3 2100+200x1000x600 | D21: =4LKD001AR+4LKD003AR | J21: =SUM(J23:J25) -> 9.5 | K21: =SUM(K23:K25) -> 9.5 | M21: =SUM(M22:M27)+(SUM(M22:M27)*0.3) -> 35.698 | O21: =SUM(O22:O27)+(SUM(O22:O27)*0.3) -> 33.0668 | P21: 3VA1063-3ED32-0AA0 - 63A 3VA9988-0AA12 AUX 1CO 3VA9157-0EK11 Rotary 3VA9152-0WA00 phase barrier -> 2 kom 3VA9111-0WD30 mala zaštita odozgora 3VA9113-0JF60 distri odozdola i izolacija | Q21: C10F3TM032 + LV429337T + LVS04033 +LV429515
B22: -F21 | C22: BELT CONVEYOR FOR BOTTOM ASH | D22: 4 FES 008 MO | E22: [4 FES 008 MO] BELT CONVEYOR FOR BOTTOM ASH | F22: CONVOYEURS À BANDES APRÈS EXTRACTEURS À MÂCHEFERS | G22: Ash system | H22: 3Ph | I22: 400 | J22: 5.5 | K22: 5.5 | M22: =ROUND(J22/(1.73*0.4),2) -> 7.95 | N22: 80 | O22: =M22*(N22/100) -> 6.36 | R22: ☑ | S22: 3RV2021-1KA10 | T22: 9 - 12.5 A | U22: SIE.3RV2901-1E 3RV2901-1A | V22: 3RT2015-1AP02 (1NC) 3RT2015-1AP02 (1NC) 3RA2913-2AA1 (interlock) | W22: 3RT2916-1CD00 (RC) 3RT2936-1CD00 (RC) 3RH2911-1HA31 (aux) 3RH2911-1HA31 (aux) | AA22: GV2P16 GVAE11 (NC+NO) GVAD0110 (NC fault + NO) | AB22: 9 - 14 A | AC22: 2x LC1D12P7 (1NO+1NC) 2x LADN31 (3NO+1NC) 2x LAD4RCU (RC) LAD9R1V (intelock blokada) | AF22: 47506015 | AH22: 3UF7011-1AU00-1 - base unit 3UF7510-1AA00-0 - ground fault 3UL2302-1A - trafo 35mm | AI22: A9F74202 | AJ22: A9F74202 | AK22: RXM4AB2E7 RXZE2S114M RXM021BN | AL22: LZS:PT5A5T30 LZS:PTMU0730 | AM22: XPSBAC34AP | AN22: U1000R2V 4G25 | AO22: 42 | AP22: 22.8 | AQ22: LV481603 + GS1AH103 + ZBE101 + GS1AM110 | AR22: NORD
B23: -F22 | C23: ASH CRUSHER 1 | D23: 4 FES 038 MO | E23: [4 FES 038 MO] ASH CRUSHER BELOW EX. ECO | F23: BROYEUR DE CENDRES SOUS L'ÉCO | G23: Ash system | H23: 3Ph | I23: 400 | J23: 4 | K23: 4 | M23: =ROUND(J23/(1.73*0.4),2) -> 5.78 | N23: 100 | O23: =M23*(N23/100) -> 5.78 | R23: ☑ | S23: 3RV2021-1JA10 | T23: 7 - 10A | U23: SIE.3RV2901-1E 3RV2901-1A | V23: 3RT2016-1AP01 (NO) 3RT2016-1AP01 (NO) 3RA2913-2AA1 (interlock) | W23: 3RT2916-1CD00 (RC) 3RT2936-1CD00 (RC) 3RH2911-1HA31 (aux) 3RH2911-1HA31 (aux) | X23: 3RW4024-1BB14 | Y23: SE.ATS22D17Q | AA23: GV2P14 GVAE11 (NC+NO) GVAD0110 (NC fault + NO) | AB23: 6 - 10 A | AC23: 2x LC1D12P7 (1NO+1NC) 2x LADN31 (3NO+1NC) 2x LAD4RCU (RC) LAD9R1V (intelock blokada) | AF23: 47506015 | AH23: 3UF7011-1AU00-1 - base unit 3UF7510-1AA00-0 - ground fault 3UL2302-1A - trafo 35mm | AI23: A9F74202 | AJ23: A9F74202 | AK23: RXM4AB2E7 RXZE2S114M RXM021BN | AL23: LZS:PT5A5T30 LZS:PTMU0730 | AM23: XPSBAC34AP | AN23: U1000R2V 4G2,5 | AO23: 32 | AP23: 11.1 | AQ23: LV481603 + GS1AH103 + ZBE101 + GS1AM110 | AR23: NORD
B24: -F23 | C24: ASH CRUSHER 2 | D24: 4 FES 040 MO | E24: [4 FES 040 MO] ASH CRUSHER BELOW SH 3 | F24: BROYEUR DE CENDRES SOUS LE SH 3 | G24: Ash system | H24: 3Ph | I24: 400 | J24: 4 | K24: 4 | M24: =ROUND(J24/(1.73*0.4),2) -> 5.78 | N24: 100 | O24: =M24*(N24/100) -> 5.78 | R24: ☑ | S24: 3RV2021-1JA10 | T24: 7 - 10A | U24: SIE.3RV2901-1E 3RV2901-1A | V24: 3RT2016-1AP01 (NO) 3RT2016-1AP01 (NO) 3RA2913-2AA1 (interlock) | W24: 3RT2916-1CD00 (RC) 3RT2936-1CD00 (RC) 3RH2911-1HA31 (aux) 3RH2911-1HA31 (aux) | X24: 3RW4024-1BB14 | Y24: SE.ATS22D17Q | AA24: GV2P14 GVAE11 (NC+NO) GVAD0110 (NC fault + NO) | AB24: 6 - 10 A | AC24: 2x LC1D12P7 (1NO+1NC) 2x LADN31 (3NO+1NC) 2x LAD4RCU (RC) LAD9R1V (intelock blokada) | AF24: 47506015 | AH24: 3UF7011-1AU00-1 - base unit 3UF7510-1AA00-0 - ground fault 3UL2302-1A - trafo 35mm | AI24: A9F74202 | AJ24: A9F74202 | AK24: RXM4AB2E7 RXZE2S114M RXM021BN | AL24: LZS:PT5A5T30 LZS:PTMU0730 | AM24: XPSBAC34AP | AN24: U1000R2V 4G2,5 | AO24: 32 | AP24: 11.1 | AQ24: LV481603 + GS1AH103 + ZBE101 + GS1AM110 | AR24: NORD
B25: -F24 | C25: CLOSED CHAIN CONVEYOR 2 | D25: 4 FES 050 MO | E25: [4 FES 050 MO] CLOSED CHAIN CONVEYOR UNDER ECO | F25: CONVOYEUR À CHAÎNE SOUS L'ÉCO | G25: Ash system | H25: 3Ph | I25: 400 | J25: 1.5 | K25: 1.5 | M25: =ROUND(J25/(1.73*0.4),2) -> 2.17 | N25: 80 | O25: =M25*(N25/100) -> 1.736 | R25: ☑ | S25: 3RV2021-1FA10 | T25: 3.5 - 5 A | U25: SIE.3RV2901-1E 3RV2901-1A | V25: 3RT2015-1AP02 (1NC) 3RT2015-1AP02 (1NC) 3RA2913-2AA1 (interlock) | W25: 3RT2916-1CD00 (RC) 3RT2936-1CD00 (RC) 3RH2911-1HA31 (aux) 3RH2911-1HA31 (aux) | AA25: GV2P08 GVAE11 (NC+NO) GVAD0110 (NC fault + NO) | AB25: 2.5 - 4 A | AC25: 2x LC1D12P7 (1NO+1NC) 2x LADN31 (3NO+1NC) 2x LAD4RCU (RC) LAD9R1V (intelock blokada) | AF25: 47506015 | AH25: 3UF7011-1AU00-1 - base unit 3UF7510-1AA00-0 - ground fault 3UL2302-1A - trafo 35mm | AI25: A9F74202 | AJ25: A9F74202 | AK25: RXM4AB2E7 RXZE2S114M RXM021BN | AL25: LZS:PT5A5T30 LZS:PTMU0730 | AM25: XPSBAC34AP | AN25: U1000R2V 4G2,5 | AO25: 32 | AP25: 11.1 | AQ25: LV481603 + GS1AH103 + ZBE101 + GS1AM110 | AR25: NORD
B26: -F25 | C26: CHAIN CONVEYOR FOR BOTTOM ASH | D26: 4 FDR 009 MO | E26: CHAIN CONVEYOR FOR BOTTOM ASH | F26: CONVOYEUR À CHAINE VERS ÉVACUATION DES CENDRES SOUS CHAUDIÈRE | G26: Ash system | H26: 3Ph | I26: 400 | J26: 4 | K26: 4 | M26: =ROUND(J26/(1.73*0.4),2) -> 5.78 | N26: 100 | O26: =M26*(N26/100) -> 5.78 | R26: ☑ | AA26: GV2P14 GVAE11 (NC+NO) GVAD0110 (NC fault + NO) | AB26: 6 - 10 A | AC26: 2x LC1D12P7 (1NO+1NC) 2x LADN31 (3NO+1NC) 2x LAD4RCU (RC) LAD9R1V (intelock blokada) | AF26: 47506015 | AI26: A9F74202 | AJ26: A9F74202 | AK26: RXM4AB2E7 RXZE2S114M RXM021BN | AL26: LZS:PT5A5T30 LZS:PTMU0730 | AM26: XPSBAC34AP | AN26: U1000R2V 4G2,5 | AO26: 32 | AP26: 11.1
B27: -F26 | C27: SPARE (prazni prostor) | E27: SPARE (prazni prostor)
B28: ORMAR 4 2100+200x1000x600 | D28: =4LKD001AR+4LKD004AR | J28: =SUM(J29:J34) -> 17 | K28: =SUM(K29:K34) -> 17 | M28: =SUM(M29:M34)+(SUM(M29:M34)*0.3) -> 31.954 | O28: =SUM(O29:O34)+(SUM(O29:O34)*0.3) -> 23.8758 | P28: 3VA1063-3ED32-0AA0 - 63A 3VA9988-0AA12 AUX 1CO 3VA9157-0EK11 Rotary 3VA9152-0WA00 phase barrier -> 2 kom 3VA9111-0WD30 mala zaštita odozgora 3VA9113-0JF60 distri odozdola i izolacija | Q28: C10F3TM032 + LV429337T + LVS04033 +LV429515
B29: -F31 | C29: Chain conveyor for distribution | D29: 4 FES 024 MO | E29: [4 FES 024 MO] CHAIN CONVEYOR FOR DISTRIBUTION | F29: CONVOYEUR À CHAINE VERS HALL DE STOCKAGE MÂCHEFERS | G29: Ash system | H29: 3Ph | I29: 400 | J29: 5.5 | K29: 5.5 | M29: =ROUND(J29/(1.73*0.4),2) -> 7.95 | N29: 100 | O29: =M29*(N29/100) -> 7.95 | P29: NOVO | R29: ☑ | S29: 3RV2021-1KA10 | T29: 9 - 12.5 A | U29: SIE.3RV2901-1E 3RV2901-1A | V29: 3RT2015-1AP02 (1NC) 3RT2015-1AP02 (1NC) 3RA2913-2AA1 (interlock) | W29: 3RT2916-1CD00 (RC) 3RT2936-1CD00 (RC) 3RH2911-1HA31 (aux) 3RH2911-1HA31 (aux) | AA29: GV2P16 GVAE11 (NC+NO) GVAD0110 (NC fault + NO) | AB29: 9 - 14 A | AC29: 2x LC1D12P7 (1NO+1NC) 2x LADN31 (3NO+1NC) 2x LAD4RCU (RC) LAD9R1V (intelock blokada) | AF29: 47506015 | AH29: 3UF7011-1AU00-1 - base unit 3UF7510-1AA00-0 - ground fault 3UL2302-1A - trafo 35mm | AI29: A9F74202 | AJ29: A9F74202 | AK29: RXM4AB2E7 RXZE2S114M RXM021BN | AL29: LZS:PT5A5T30 LZS:PTMU0730 | AM29: XPSBAC34AP | AN29: U1000R2V 4G2,5 | AO29: 42 | AP29: 11.1 | AQ29: LV481603 + GS1AH103 + ZBE101 + GS1AM110 | AR29: NORD
B30: -F32 | C30: Rotary dispenser 1 | D30: 4 FES 012 MO | E30: [4 FES 012 MO] ROTARY DISPENSER BELOW EX. ECO | F30: SAS ROTATIF SOUS L'ÉCO | G30: Ash system | H30: 3Ph | I30: 400 | J30: 3 | K30: 3 | M30: =ROUND(J30/(1.73*0.4),2) -> 4.34 | N30: 100 | O30: =M30*(N30/100) -> 4.34 | R30: ☑ | S30: 3RV2021-1HA10 | T30: 5.5 - 8 A | U30: SIE.3RV2901-1E 3RV2901-1A | V30: 3RT2015-1AP02 (1NC) 3RT2015-1AP02 (1NC) 3RA2913-2AA1 (interlock) | W30: 3RT2916-1CD00 (RC) 3RT2936-1CD00 (RC) 3RH2911-1HA31 (aux) 3RH2911-1HA31 (aux) | AA30: GV2P14 GVAE11 (NC+NO) GVAD0110 (NC fault + NO) | AB30: 6 - 10 A | AC30: 2x LC1D12P7 (1NO+1NC) 2x LADN31 (3NO+1NC) 2x LAD4RCU (RC) LAD9R1V (intelock blokada) | AF30: 47506015 | AH30: 3UF7011-1AU00-1 - base unit 3UF7510-1AA00-0 - ground fault 3UL2302-1A - trafo 35mm | AI30: A9F74202 | AJ30: A9F74202 | AK30: RXM4AB2E7 RXZE2S114M RXM021BN | AL30: LZS:PT5A5T30 LZS:PTMU0730 | AM30: XPSBAC34AP | AN30: U1000R2V 4G2,5 | AO30: 32 | AP30: 11.1 | AQ30: LV481603 + GS1AH103 + ZBE101 + GS1AM110 | AR30: NORD
B31: -F33 | C31: Rotary dispenser 2 | D31: 4 FES 014 MO | E31: [4 FES 014 MO] ROTARY DISPENSER BELOW SH 3 | F31: DISTRIBUTEUR ROTATIF SOUS LE SH 3 | G31: Ash system | H31: 3Ph | I31: 400 | J31: 3 | K31: 3 | M31: =ROUND(J31/(1.73*0.4),2) -> 4.34 | N31: 100 | O31: =M31*(N31/100) -> 4.34 | R31: ☑ | S31: 3RV2021-1HA10 | T31: 5.5 - 8 A | U31: SIE.3RV2901-1E 3RV2901-1A | V31: 3RT2015-1AP02 (1NC) 3RT2015-1AP02 (1NC) 3RA2913-2AA1 (interlock) | W31: 3RT2916-1CD00 (RC) 3RT2936-1CD00 (RC) 3RH2911-1HA31 (aux) 3RH2911-1HA31 (aux) | AA31: GV2P14 GVAE11 (NC+NO) GVAD0110 (NC fault + NO) | AB31: 6 - 10 A | AC31: 2x LC1D12P7 (1NO+1NC) 2x LADN31 (3NO+1NC) 2x LAD4RCU (RC) LAD9R1V (intelock blokada) | AF31: 47506015 | AH31: 3UF7011-1AU00-1 - base unit 3UF7510-1AA00-0 - ground fault 3UL2302-1A - trafo 35mm | AI31: A9F74202 | AJ31: A9F74202 | AK31: RXM4AB2E7 RXZE2S114M RXM021BN | AL31: LZS:PT5A5T30 LZS:PTMU0730 | AM31: XPSBAC34AP | AN31: U1000R2V 4G2,5 | AO31: 32 | AP31: 11.1 | AQ31: LV481603 + GS1AH103 + ZBE101 + GS1AM110 | AR31: NORD
B32: -F34 | C32: CLOSED CHAIN CONVEYOR 3 | D32: 4 FES 010 MO | E32: [4 FES 010 MO] CLOSED CHAIN CONVEYOR FOR ASH DISPATCH | F32: CONVOYEUR À CHAINE VERS ÉVACUATION DES CENDRES SOUS CHAUDIÈRE | G32: Ash system | H32: 3Ph | I32: 400 | J32: 1.5 | K32: 1.5 | M32: =ROUND(J32/(1.73*0.4),2) -> 2.17 | N32: 80 | O32: =M32*(N32/100) -> 1.736 | R32: ☑ | S32: 3RV2021-1FA10 | T32: 3.5 - 5 A | U32: SIE.3RV2901-1E 3RV2901-1A | V32: 3RT2015-1AP02 (1NC) 3RT2015-1AP02 (1NC) 3RA2913-2AA1 (interlock) | W32: 3RT2916-1CD00 (RC) 3RT2936-1CD00 (RC) 3RH2911-1HA31 (aux) 3RH2911-1HA31 (aux) | AA32: GV2P08 GVAE11 (NC+NO) GVAD0110 (NC fault + NO) | AB32: 2.5 - 4 A | AC32: 2x LC1D12P7 (1NO+1NC) 2x LADN31 (3NO+1NC) 2x LAD4RCU (RC) LAD9R1V (intelock blokada) | AF32: 47506015 | AH32: 3UF7011-1AU00-1 - base unit 3UF7510-1AA00-0 - ground fault 3UL2302-1A - trafo 35mm | AI32: A9F74202 | AJ32: A9F74202 | AK32: RXM4AB2E7 RXZE2S114M RXM021BN | AL32: LZS:PT5A5T30 LZS:PTMU0730 | AM32: XPSBAC34AP | AN32: U1000R2V 4G2,5 | AO32: 32 | AP32: 11.1 | AQ32: LV481603 + GS1AH103 + ZBE101 + GS1AM110 | AR32: NORD
A33: korigiran potrošač 13.07.2026. | B33: -F35 | C33: SPARE (prazni prostor) | D33: BIO JE: SPARE (prazan prostor) 4SAR902MO | E33: [4SAR902MO] FURNACE REFRACTORY COOLING FANS 1 | F33: VENTILATEURS DE REFROIDISSEMENT RÉFRACTAIRES POUR FOURNAISE 1 | H33: 3Ph | I33: 400 | J33: 4 | K33: 4 | M33: =ROUND(J33/(1.73*0.4),2) -> 5.78 | AA33: GV2P14 GVAE11 (NC+NO) GVAD0110 (NC fault + NO) | AB33: 6 - 10 A | AC33: LC1D12P7 (1NO+1NC) LADN31 (3NO+1NC) LAD4RCU (RC) | AF33: 47506015 | AJ33: A9F74202 | AK33: A9F74202 | AL33: RXM4AB2E7 RXZE2S114M RXM021BN | AM33: LZS:PT5A5T30 LZS:PTMU0730 | AN33: XPSBAC34AP
B34: -F36 | C34: SPARE (prazni prostor) | E34: SPARE (prazni prostor)
B35: ORMAR 5 2100+200x1000x600 | D35: =4LKD001AR+4LKD005AR | J35: =SUM(J36:J39) -> 14 | K35: =SUM(K36:K39) -> 14 | M35: =SUM(M36:M41)+(SUM(M36:M41)*0.3) -> 26.312 | O35: =SUM(O36:O41)+(SUM(O36:O41)*0.3) -> 26.312 | P35: 3VA1032-3ED32-0AA0 - 32A 3VA9988-0AA12 AUX 1CO 3VA9157-0EK11 Rotary 3VA9152-0WA00 phase barrier -> 2 kom 3VA9111-0WD30 mala zaštita odozgora 3VA9113-0JF60 distri odozdola i izolacija | Q35: C10F3TM032 + LV429337T + LVS04033 +LV429515
B36: -F41 | C36: ASH CRUSHER 3 | D36: 4 FES 042 MO | E36: [4 FES 042 MO] ASH CRUSHER BELOW SH 2 | F36: BROYEUR DE CENDRES SOUS LE SH 2 | G36: Ash system | H36: 3Ph | I36: 400 | J36: 4 | K36: 4 | M36: =ROUND(J36/(1.73*0.4),2) -> 5.78 | N36: 100 | O36: =M36*(N36/100) -> 5.78 | R36: ☑ | S36: 3RV2021-1JA10 | T36: 7 - 10A | U36: SIE.3RV2901-1E 3RV2901-1A | V36: 3RT2016-1AP01 (NO) 3RT2016-1AP01 (NO) 3RA2913-2AA1 (interlock) | W36: 3RT2916-1CD00 (RC) 3RT2936-1CD00 (RC) 3RH2911-1HA31 (aux) 3RH2911-1HA31 (aux) | X36: 3RW4024-1BB14 | Y36: SE.ATS22D17Q | AA36: GV2P14 GVAE11 (NC+NO) GVAD0110 (NC fault + NO) | AB36: 6 - 10 A | AC36: 2x LC1D12P7 (1NO+1NC) 2x LADN31 (3NO+1NC) 2x LAD4RCU (RC) LAD9R1V (intelock blokada) | AF36: 47506015 | AH36: 3UF7011-1AU00-1 - base unit 3UF7510-1AA00-0 - ground fault 3UL2302-1A - trafo 35mm | AI36: A9F74202 | AJ36: A9F74202 | AK36: RXM4AB2E7 RXZE2S114M RXM021BN | AL36: LZS:PT5A5T30 LZS:PTMU0730 | AM36: XPSBAC34AP | AN36: U1000R2V 4G2,5 | AO36: 32 | AP36: 11.1 | AQ36: LV481603 + GS1AH103 + ZBE101 + GS1AM110 | AR36: NORD
B37: -F42 | C37: ASH CRUSHER 4 | D37: 4 FES 044 MO | E37: [4 FES 044 MO] ASH CRUSHER BELOW SH 1 | F37: BROYEUR DE CENDRES SOUS LE SH 1 | G37: Ash system | H37: 3Ph | I37: 400 | J37: 4 | K37: 4 | M37: =ROUND(J37/(1.73*0.4),2) -> 5.78 | N37: 100 | O37: =M37*(N37/100) -> 5.78 | R37: ☑ | S37: 3RV2021-1JA10 | T37: 7 - 10A | U37: SIE.3RV2901-1E 3RV2901-1A | V37: 3RT2016-1AP01 (NO) 3RT2016-1AP01 (NO) 3RA2913-2AA1 (interlock) | W37: 3RT2916-1CD00 (RC) 3RT2936-1CD00 (RC) 3RH2911-1HA31 (aux) 3RH2911-1HA31 (aux) | X37: 3RW4024-1BB14 | Y37: SE.ATS22D17Q | AA37: GV2P14 GVAE11 (NC+NO) GVAD0110 (NC fault + NO) | AB37: 6 - 10 A | AC37: 2x LC1D12P7 (1NO+1NC) 2x LADN31 (3NO+1NC) 2x LAD4RCU (RC) LAD9R1V (intelock blokada) | AF37: 47506015 | AH37: 3UF7011-1AU00-1 - base unit 3UF7510-1AA00-0 - ground fault 3UL2302-1A - trafo 35mm | AI37: A9F74202 | AJ37: A9F74202 | AK37: RXM4AB2E7 RXZE2S114M RXM021BN | AL37: LZS:PT5A5T30 LZS:PTMU0730 | AM37: XPSBAC34AP | AN37: U1000R2V 4G2,5 | AO37: 32 | AP37: 11.1 | AQ37: LV481603 + GS1AH103 + ZBE101 + GS1AM110 | AR37: NORD
B38: -F43 | C38: Rotary dispenser 3 | D38: 4 FES 016 MO | E38: [4 FES 016 MO] ROTARY DISPENSER BELOW SH 2 | F38: SAS ROTATIF SOUS LE SH 2 | G38: Ash system | H38: 3Ph | I38: 400 | J38: 3 | K38: 3 | M38: =ROUND(J38/(1.73*0.4),2) -> 4.34 | N38: 100 | O38: =M38*(N38/100) -> 4.34 | R38: ☑ | S38: 3RV2021-1HA10 | T38: 5.5 - 8 A | U38: SIE.3RV2901-1E 3RV2901-1A | V38: 3RT2015-1AP02 (1NC) 3RT2015-1AP02 (1NC) 3RA2913-2AA1 (interlock) | W38: 3RT2916-1CD00 (RC) 3RT2936-1CD00 (RC) 3RH2911-1HA31 (aux) 3RH2911-1HA31 (aux) | AA38: GV2P14 GVAE11 (NC+NO) GVAD0110 (NC fault + NO) | AB38: 6 - 10 A | AC38: 2x LC1D12P7 (1NO+1NC) 2x LADN31 (3NO+1NC) 2x LAD4RCU (RC) LAD9R1V (intelock blokada) | AF38: 47506015 | AH38: 3UF7011-1AU00-1 - base unit 3UF7510-1AA00-0 - ground fault 3UL2302-1A - trafo 35mm | AI38: A9F74202 | AJ38: A9F74202 | AK38: RXM4AB2E7 RXZE2S114M RXM021BN | AL38: LZS:PT5A5T30 LZS:PTMU0730 | AM38: XPSBAC34AP | AN38: U1000R2V 4G2,5 | AO38: 32 | AP38: 11.1 | AQ38: LV481603 + GS1AH103 + ZBE101 + GS1AM110 | AR38: NORD
B39: -F44 | C39: Rotary dispenser 4 | D39: 4 FES 018 MO | E39: [4 FES 018 MO] ROTARY DISPENSER BELOW SH 1 | F39: SAS ROTATIF SOUS LE SH 1 | G39: Ash system | H39: 3Ph | I39: 400 | J39: 3 | K39: 3 | M39: =ROUND(J39/(1.73*0.4),2) -> 4.34 | N39: 100 | O39: =M39*(N39/100) -> 4.34 | R39: ☑ | S39: 3RV2021-1HA10 | T39: 5.5 - 8 A | U39: SIE.3RV2901-1E 3RV2901-1A | V39: 3RT2015-1AP02 (1NC) 3RT2015-1AP02 (1NC) 3RA2913-2AA1 (interlock) | W39: 3RT2916-1CD00 (RC) 3RT2936-1CD00 (RC) 3RH2911-1HA31 (aux) 3RH2911-1HA31 (aux) | AA39: GV2P14 GVAE11 (NC+NO) GVAD0110 (NC fault + NO) | AB39: 6 - 10 A | AC39: 2x LC1D12P7 (1NO+1NC) 2x LADN31 (3NO+1NC) 2x LAD4RCU (RC) LAD9R1V (intelock blokada) | AF39: 47506015 | AH39: 3UF7011-1AU00-1 - base unit 3UF7510-1AA00-0 - ground fault 3UL2302-1A - trafo 35mm | AI39: A9F74202 | AJ39: A9F74202 | AK39: RXM4AB2E7 RXZE2S114M RXM021BN | AL39: LZS:PT5A5T30 LZS:PTMU0730 | AM39: XPSBAC34AP | AN39: U1000R2V 4G2,5 | AO39: 32 | AP39: 11.1 | AQ39: LV481603 + GS1AH103 + ZBE101 + GS1AM110 | AR39: NORD
B40: -F45 | C40: SPARE (prazni prostor) | E40: SPARE (prazni prostor)
...

Sheet Emerg Boiler MCC distribution
A1: Napomena | B1: Emergency Boiler MCC 4LKF001AR | E1: BOILER/LOW VOLTAGE CABINET BOILER (EMERGENCY) | F1: CHAUDIÈRE/ARMOIRE BASSE TENSION CHAUDIÈRE (SECOURUE) | M1: spare 25% -> postavljeno 30% | P1: 25kA! | Q1: 36kA!!!!!!!!!!!!
B2: Oznaka EPLAN | C2: KKS OLD | D2: KKS prekidača | E2: KKS NEW | F2: KKS NEW - prijevod | G2: PID | H2: 1Ph/3Ph | I2: V | J2: kW | K2: EPLAN kW | L2: kA | M2: Struja motora [A] | N2: Simultaneity factor in maximal normal mode [%] | O2: Struja prekidača s faktorom [A] | P2: Dovodni prekidač SIEMENS | Q2: Dovodni prekidač SCHNEIDER | R2: Rastavna sklopka | S2: Reverzibilni | T2: Motorna zaštita Siemens | U2: Motorna zaštita A Siemens | V2: Motorna zaštita AUX Siemens | W2: Sklopnik minimum 12A Siemens | X2: Sklopnik AUX + RC element Siemens | Y2: Motorna zaštita Schneider | Z2: Motorna zaštita A Schneider | AA2: Motorna zaštita A Schneider | AB2: 1F Strujni trafo ampermetar | AC2: Mjerni strujni trafo za 3F el. Measurement - Socomec | AD2: Dozemni spoj - Socomec | AE2: Frekventni | AF2: Soft starter | AG2: Prekidač za 400VAC | AH2: Prekidač za 230VAC | AI2: Prekidač za 48VAC | AJ2: RELEJ 48VAC minimum 6A | AK2: RELEJ 230VAC minimum 6A | AL2: Safety relay | AM2: Tip kabela | AN2: Strujno opterećenje kabela | AO2: vanjski promjer kabela | AP2: Proizvođač motora | AQ2: Klematura | AR2: Napomena
B3: ORMAR 1 2100+200x1000x600 | D3: =4LKF001AR+4LKF001AR | M3: =SUM(M19,M26,M9,M33,M38) -> 543.92 | O3: =SUM(O19,O26,O9,O33,O38) -> 327.8535 | P3: SIE.3KD2832-0NE10-0 (80A) SIE.3KD9103-5 3KD9204-7 (cable cover) | Q3: C40F32D400 + LV432597T + 2x LV432593
Q4: INS 400 - SE.31110 29450 (NO/NC) 2xLV432594 (cover) | R4: LV481453 -> ispod ide odvodnik prenapona
D5: Predikač prije odvodnika - | AC5: 3x 48290573
D6: Odvodnik prenapona - 5SD7473-1 A9L40321 - Schnider odvodnik prenapona
D7: Nadzor faza - 3UG5514-1BR20
D8: Okretno polje -
B9: ORMAR 2 2100+200x1000x600 | D9: =4LKF001AR+4LKF002AR | J9: =SUM(J10:J18) -> 56.3 | K9: =SUM(K10:K18) -> 46.3 | M9: =SUM(M10:M18)+(SUM(M10:M18)*0.3) -> 146.731 | O9: =SUM(O10:O18)+(SUM(O10:O18)*0.3) -> 131.6965 | P9: 3VA1032-3ED32-0AA0 - 32A 3VA9988-0AA12 AUX 1CO 3VA9157-0EK11 Rotary 3VA9152-0WA00 phase barrier -> 2 kom 3VA9111-0WD30 mala zaštita odozgora 3VA9113-0JF60 distri odozdola i izolacija | Q9: SE.C16F3TM125 - 125A 36kA +29450 (1CO) +LV429337T (rotary) +LVS04033 (distriblock dole) +LV429517 (duga zaštita)
B10: -F11 | C10: Ash steam vent fan | D10: 4 DEM 071 MO | E10: [4 DEM 071 MO] ASH STEAM VENT FAN | F10: VENTILATEUR DES BUÉES | G10: Ash removal system | H10: 3Ph | I10: 400 | J10: 0.5 | K10: 0.5 | L10: 25 | M10: =ROUND(J10/(1.73*0.4),2) -> 0.72 | N10: 100 | O10: =M10*(N10/100) -> 0.72 | T10: 3RV2021-1AA10 | U10: 1.1 - 1.6 A | V10: SIE.3RV2901-1E 3RV2901-1A | W10: 3RT2015-1AP02 (1NC) | X10: 3RT2916-1CD00 3RH2911-1HA31 | Y10: GV2P06 GVAE11 (NC+NO) GVAD0110 (NC fault + NO) | Z10: 1 - 1.6 A | AA10: LC1D12P7 (1NO+1NC) LADN31 (3NO+1NC) LAD4RCU (RC) | AD10: 47506015 | AH10: A9F74202 | AI10: A9F74202 | AJ10: RXM4AB2E7 RXZE2S114M RXM021BN | AK10: RXM4AB2P7 RXZE2S114M RXM021FP | AL10: XPSBAC34AP | AM10: U1000R2V 4G2,5 | AN10: 32 | AO10: 11.1
B11: -F12 | C11: Cooling pump 1 | D11: 4 FGR 484 MO | E11: [4 FGR 484 MO] HPU COOLING PUMP | F11: POMPE DE REFROIDISSEMENT HPU | G11: Hydraulic cylinder | H11: 3Ph | I11: 400 | J11: 3 | K11: 3 | L11: 25 | M11: =ROUND(J11/(1.73*0.4),2) -> 4.34 | N11: 0 | O11: =M11*(N11/100) -> 0 | T11: 3RV2021-1HA10 | U11: 5.5 - 8 A | V11: SIE.3RV2901-1E 3RV2901-1A | W11: 3RT2015-1AP02 (1NC) | X11: 3RT2916-1CD00 3RH2911-1HA31 | Y11: GV2P14 GVAE11 (NC+NO) GVAD0110 (NC fault + NO) | Z11: 6 - 10 A | AA11: LC1D12P7 (1NO+1NC) LADN31 (3NO+1NC) LAD4RCU (RC) | AD11: 47506015 | AH11: A9F74202 | AI11: A9F74202 | AJ11: RXM4AB2E7 RXZE2S114M RXM021BN | AK11: LZS:PT5A5T30 LZS:PTMU0730 | AL11: XPSBAC34AP | AM11: U1000R2V 4G2,5 | AN11: 32 | AO11: 11.1
B12: -F13 | C12: Cooling fan 1 | D12: 4 FGR 494 ZV | E12: [4 FGR 494 ZV] COOLING FAN 1 | F12: VENTILATEUR DE REFROIDISSEMENT 1 | G12: Hydraulic cylinder | H12: 3Ph | I12: 400 | J12: 0.8 | K12: 0.8 | L12: 25 | M12: =ROUND(J12/(1.73*0.4),2) -> 1.16 | N12: 100 | O12: =M12*(N12/100) -> 1.16 | T12: 3RV2021-1CA10 | U12: 1.8 - 2.5 A | V12: SIE.3RV2901-1E 3RV2901-1A | W12: 3RT2015-1AP02 (1NC) | X12: 3RT2916-1CD00 3RH2911-1HA31 | Y12: GV2P08 GVAE11 (NC+NO) GVAD0110 (NC fault + NO) | Z12: 2.5 - 4 A | AA12: LC1D12P7 (1NO+1NC) LADN31 (3NO+1NC) LAD4RCU (RC) | AD12: 47506015 | AH12: A9F74202 | AI12: A9F74202 | AJ12: RXM4AB2E7 RXZE2S114M RXM021BN | AK12: LZS:PT5A5T30 LZS:PTMU0730 | AL12: XPSBAC34AP | AM12: U1000R2V 4G2,5 | AN12: 32 | AO12: 11.1
B13: -F14 | D13: 4CRF152AR | E13: [4CRF152AR] EMERGENCY COOLER | F13: REFROIDISSEUR D'URGENCE | H13: 3Ph | I13: 400 | J13: 19.2 | K13: 19.2 | L13: 25 | M13: =ROUND(J13/(1.73*0.4),2) -> 27.75 | N13: 100 | O13: =M13*(N13/100) -> 27.75 | P13: NSX 32A | Q13: NG125 - 18727 - 32A +19072 (1CO) | R13: C10F3TM032 - 32A +29450 (1CO) +LV429337T (rotary) +LVS04033 (distriblock dole) +LV429517 (duga zaštita) | AB13: 192T2106 CT 60A 192A1204 (0-40A) | AC13: 3x 48290501 | AD13: 47506015 | AM13: U1000R2V 4G6 | AO13: 14.3
B14: -F15 | D14: 4CTE111CR | E14: [??] EXPANSION TANK SYSTEM | F14: RÉSERVOIR D'EXPANSION | H14: 3Ph | I14: 400 | J14: 10 | K14: 10 | L14: 25 | M14: =ROUND(J14/(1.73*0.4),2) -> 14.45 | N14: 50 | O14: =M14*(N14/100) -> 7.225 | P14: NSX 32A | Q14: NG125 - 18727 - 32A +19072 (1CO) | R14: C10F3TM032 - 32A +29450 (1CO) +LV429337T (rotary) +LVS04033 (distriblock dole) +LV429517 (duga zaštita) | AD14: 47506015 | AM14: U1000R2V 4G2,5 | AO14: 11.1
B15: -F16 | D15: 4CTE066AR | E15: [4CTE066AR] WATER COOLER 1 | F15: REFROIDISSEUR D'EAU 1 | H15: 3Ph | I15: 400 | J15: =(3.2*6)/3 -> 6.4 | K15: =(3.2*6)/3 -> 6.4 | L15: 25 | M15: 25 | N15: 100 | O15: =M15*(N15/100) -> 25 | P15: NSX 25A | Q15: NG125 - 18726 - 25A +19072 (1CO) | R15: C10F3TM025 - 25A +29450 (1CO) +LV429337T (rotary) +LVS04033 (distriblock dole) +LV429517 (duga zaštita) | AD15: 47506015 | AM15: U1000R2V 4G4 | AO15: 12.3
B16: -F17 | D16: 4CTE065AR | E16: [4CTE065AR] WATER COOLER 2 | F16: REFROIDISSEUR D'EAU 2 | H16: 3Ph | I16: 400 | J16: =(3.2*6)/3 -> 6.4 | K16: =(3.2*6)/3 -> 6.4 | L16: 25 | M16: 25 | N16: 100 | O16: =M16*(N16/100) -> 25 | P16: NSX 25A | Q16: NG125 - 18726 - 25A +19072 (1CO) | R16: C10F3TM025 - 25A +29450 (1CO) +LV429337T (rotary) +LVS04033 (distriblock dole) +LV429517 (duga zaštita) | AD16: 47506015 | AM16: U1000R2V 4G4 | AO16: 12.3
B17: -F18 - naknadno dodano na terenu postaviti prekidač | C17: SPARE (prazni prostor) | E17: [??] GRATE EXPANSION TANK SYSTEM | F17: SYSTÈME DE RÉSERVOIR D'EXPANSION | H17: 3Ph | I17: 400 | J17: 10 | K17: UBACITI U SHEME i naručiti opremu | L17: 25 | M17: =ROUND(J17/(1.73*0.4),2) -> 14.45 | N17: 100 | O17: =M17*(N17/100) -> 14.45 | Q17: NG125 - 18727 - 32A +19072 (1CO) | AM17: U1000R2V 4G2,5 | AO17: 11.1
B18: -F19 | C18: SPARE (prazni prostor) | E18: SPARE (prazni prostor)
B19: ORMAR 3 2100+200x1000x600 | D19: =4LKF001AR+4LKF003AR | J19: =SUM(J20:J25) -> 16.2 | K19: =SUM(K20:K25) -> 16.2 | M19: =SUM(M20:M25)+(SUM(M20:M25)*0.3) -> 20.111 | O19: =SUM(O20:O25)+(SUM(O20:O25)*0.3) -> 20.111 | P19: 3VA1032-3ED32-0AA0 - 32A 3VA9988-0AA12 AUX 1CO 3VA9157-0EK11 Rotary 3VA9152-0WA00 phase barrier -> 2 kom 3VA9111-0WD30 mala zaštita odozgora 3VA9113-0JF60 distri odozdola i izolacija | Q19: C10F3TM032 - 32A +29450 (1CO) +LV429337T (rotary) +LVS04033 (distriblock dole) +LV429517 (duga zaštita)
B20: -F21 | C20: Cooling pump 2 | D20: 4 FGR 496 MO | E20: [4 FGR 496 MO] HPU EMERGENCY COOLING PUMP | F20: POMPE DE REFROIDISSEMENT D'URGENCE GROUPE HYDRAULIQUE | G20: Hydraulic cylinder | H20: 3Ph | I20: 400 | J20: 7.5 | K20: 7.5 | L20: 25 | M20: =ROUND(J20/(1.73*0.4),2) -> 10.84 | N20: 100 | O20: =M20*(N20/100) -> 10.84 | T20: 3RV2021-4BA10 | U20: 13 - 20 A | V20: SIE.3RV2901-1E 3RV2901-1A | W20: 3RT2018-1AP02 (1NC) | X20: 3RT2916-1CD00 3RH2911-1HA31 | Y20: GV2P20 GVAE11 (NC+NO) GVAD0110 (NC fault + NO) | Z20: 13 - 18 A | AA20: LC1D18P7 LADN31 (3NO+1NC) LAD4RCU (RC) | AB20: 192T2106 CT 60A 192A1202 (0-15A) | AC20: 3x 48290500 | AD20: 47506015 | AH20: A9F74202 | AI20: A9F74202 | AJ20: RXM4AB2E7 RXZE2S114M RXM021BN | AK20: LZS:PT5A5T30 LZS:PTMU0730 | AL20: XPSBAC34AP | AM20: U1000R2V 4G2,5 | AN20: 53 | AO20: 11.1
A21: korigiran potrošač 13.07.2026. | B21: -F22 - SPARE | C21: Cooling water pump 1 | D21: SPARE BIO JE: [4 CTE 063 PO] COOLING WATER PUMP 1 | E21: 4 FGO 003 MO LIGHT FUEL OIL PUMP 1 | F21: 4 FGO 003 MO POMPE À FIOUL LÉGER 1 | G21: DOL | H21: 3Ph | I21: 400 | J21: 5.5 | K21: 5.5 | T21: 3RV2021-1KA10 | U21: 9 - 12.5 A | V21: SIE.3RV2901-1E 3RV2901-1A | W21: 3RT2017-1AP02 (1NC) | X21: 3RT2916-1CD00 3RH2911-1HA31 | Y21: GV2P16 GVAE11 (NC+NO) GVAD0110 (NC fault + NO) | Z21: 9 - 14 A | AA21: LC1D12P7 (1NO+1NC) LADN31 (3NO+1NC) LAD4RCU (RC) | AD21: 47506015 | AH21: A9F74202 | AI21: A9F74202 | AJ21: RXM4AB2E7 RXZE2S114M RXM021BN | AK21: LZS:PT5A5T30 LZS:PTMU0730 | AL21: XPSBAC34AP
B22: -F23 | C22: Drag chain conveyor 1 | D22: 4 DEM 055 MO | E22: [4 DEM 055 MO] DRAG CHAIN CONVEYOR 1 | F22: CONVOYEUR SOUS GRILLE 1 | G22: Ash removal system | H22: 3Ph | I22: 400 | J22: 1.5 | K22: 1.5 | L22: 25 | M22: =ROUND(J22/(1.73*0.4),2) -> 2.17 | N22: 100 | O22: =M22*(N22/100) -> 2.17 | S22: ☑ | T22: 3RV2021-1FA10 | U22: 3.5 - 5 A | V22: SIE.3RV2901-1E 3RV2901-1A | W22: 3RT2016-1AP01 (NO) 3RT2016-1AP01 (NO) 3RA2913-2AA1 (interlock) | X22: 3RT2916-1CD00 (RC) 3RT2936-1CD00 (RC) 3RH2911-1HA31 (aux) 3RH2911-1HA31 (aux) | Y22: GV2P08 GVAE11 (NC+NO) GVAD0110 (NC fault + NO) | Z22: 2.5 - 4 A | AA22: LC2D12P7 (1NO+1NC) 2x LADN31 (3NO+1NC) 2x LAD4RCU (RC) | AD22: 47506015 | AH22: A9F74202 | AI22: A9F74202 | AJ22: RXM4AB2E7 RXZE2S114M RXM021BN | AK22: LZS:PT5A5T30 LZS:PTMU0730 | AL22: XPSBAC34AP | AM22: U1000R2V 4G2,5 | AN22: 32 | AO22: 11.1
B23: -F24 | C23: Sealing air fan 1 | D23: 4 FGR 146 MO | E23: [4 FGR 146 MO] SEALING AIR FAN LEFT | F23: VENTILATEUR D'AIR D'ÉTANCHÉITÉ GAUCHE | G23: Primary air system | H23: 3Ph | I23: 400 | J23: 0.9 | K23: 0.9 | L23: 25 | M23: =ROUND(J23/(1.73*0.4),2) -> 1.3 | N23: 100 | O23: =M23*(N23/100) -> 1.3 | T23: 3RV2021-1DA10 | U23: 2.2 - 3.2 A | V23: SIE.3RV2901-1E 3RV2901-1A | W23: 3RT2015-1AP02 (1NC) | X23: 3RT2916-1CD00 3RH2911-1HA31 | Y23: GV2P08 GVAE11 (NC+NO) GVAD0110 (NC fault + NO) | Z23: 2.5 - 4 A | AA23: LC1D12P7 (1NO+1NC) LADN31 (3NO+1NC) LAD4RCU (RC) | AD23: 47506015 | AH23: A9F74202 | AI23: A9F74202 | AJ23: RXM4AB2E7 RXZE2S114M RXM021BN | AK23: LZS:PT5A5T30 LZS:PTMU0730 | AL23: XPSBAC34AP | AM23: U1000R2V 4G2,5 | AN23: 32 | AO23: 11.1
B24: -F25 | C24: Cooling fan 2 | D24: 4 FGR 493 ZV | E24: [4 FGR 493 ZV] COOLING FAN 2 | F24: VENTILATEUR DE REFROIDISSEMENT 2 | G24: Hydraulic cylinder | H24: 3Ph | I24: 400 | J24: 0.8 | K24: 0.8 | L24: 25 | M24: =ROUND(J24/(1.73*0.4),2) -> 1.16 | N24: 100 | O24: =M24*(N24/100) -> 1.16 | T24: 3RV2021-1CA10 | U24: 1.8 - 2.5 A | V24: SIE.3RV2901-1E 3RV2901-1A | W24: 3RT2015-1AP02 (1NC) | X24: 3RT2916-1CD00 3RH2911-1HA31 | Y24: GV2P08 GVAE11 (NC+NO) GVAD0110 (NC fault + NO) | Z24: 2.5 - 4 A | AA24: LC1D12P7 (1NO+1NC) LADN31 (3NO+1NC) LAD4RCU (RC) | AD24: 47506015 | AH24: A9F74202 | AI24: A9F74202 | AJ24: RXM4AB2E7 RXZE2S114M RXM021BN | AK24: LZS:PT5A5T30 LZS:PTMU0730 | AL24: XPSBAC34AP | AM24: U1000R2V 4G2,5 | AN24: 32 | AO24: 11.1
B25: -F26 | C25: SPARE (prazni prostor) | E25: SPARE (prazni prostor)
B26: ORMAR 4 2100+200x1000x600 | D26: =4LKF001AR+4LKF004AR | J26: =SUM(J27:J32) -> 8.7 | K26: =SUM(K27:K32) -> 8.7 | M26: =SUM(M27:M32)+(SUM(M27:M32)*0.3) -> 16.354 | O26: =SUM(O27:O32)+(SUM(O27:O32)*0.3) -> 6.019 | P26: 3VA1032-3ED32-0AA0 - 32A 3VA9988-0AA12 AUX 1CO 3VA9157-0EK11 Rotary 3VA9152-0WA00 phase barrier -> 2 kom 3VA9111-0WD30 mala zaštita odozgora 3VA9113-0JF60 distri odozdola i izolacija | Q26: C10F3TM032 - 32A +29450 (1CO) +LV429337T (rotary) +LVS04033 (distriblock dole) +LV429517 (duga zaštita)
A27: korigiran potrošač 13.07.2026. | B27: -F31 - SPARE | C27: Cooling water pump 2 | D27: SPARE BIO JE: [4 CTE 064 PO] COOLING WATER PUMP 2 | E27: 4 FGO 004 MO LIGHT FUEL OIL PUMP 2 | F27: 4 FGO 004 MO POMPE À FIOUL LÉGER 2 | G27: DOL | H27: 3Ph | I27: 400 | J27: 5.5 | K27: 5.5 | L27: 25 | M27: =ROUND(J27/(1.73*0.4),2) -> 7.95 | N27: 0 | O27: =M27*(N27/100) -> 0 | T27: 3RV2021-1KA10 | U27: 9 - 12.5 A | V27: SIE.3RV2901-1E 3RV2901-1A | W27: 3RT2017-1AP02 (1NC) | X27: 3RT2916-1CD00 3RH2911-1HA31 | Y27: GV2P16 GVAE11 (NC+NO) GVAD0110 (NC fault + NO) | Z27: 9 - 14 A | AA27: LC1D12P7 (1NO+1NC) LADN31 (3NO+1NC) LAD4RCU (RC) | AD27: 47506015 | AH27: A9F74202 | AI27: A9F74202 | AJ27: RXM4AB2E7 RXZE2S114M RXM021BN | AK27: LZS:PT5A5T30 LZS:PTMU0730 | AL27: XPSBAC34AP
B28: -F32 | C28: Drag chain conveyor 2 | D28: 4 DEM 066 MO | E28: [4 DEM 066 MO] DRAG CHAIN CONVEYOR 2 | F28: CONVOYEUR SOUS GRILLE 2 | G28: Ash removal system | H28: 3Ph | I28: 400 | J28: 1.5 | K28: 1.5 | L28: 25 | M28: =ROUND(J28/(1.73*0.4),2) -> 2.17 | N28: 100 | O28: =M28*(N28/100) -> 2.17 | S28: ☑ | T28: 3RV2021-1FA10 | U28: 3.5 - 5 A | V28: SIE.3RV2901-1E 3RV2901-1A | W28: 3RT2016-1AP01 (NO) 3RT2016-1AP01 (NO) 3RA2913-2AA1 (interlock) | X28: 3RT2916-1CD00 (RC) 3RT2936-1CD00 (RC) 3RH2911-1HA31 (aux) 3RH2911-1HA31 (aux) | Y28: GV2P08 GVAE11 (NC+NO) GVAD0110 (NC fault + NO) | Z28: 2.5 - 4 A | AA28: LC2D12P7 (1NO+1NC) 2x LADN31 (3NO+1NC) 2x LAD4RCU (RC) | AD28: 47506015 | AH28: A9F74202 | AI28: A9F74202 | AJ28: RXM4AB2E7 RXZE2S114M RXM021BN | AK28: LZS:PT5A5T30 LZS:PTMU0730 | AL28: XPSBAC34AP | AM28: U1000R2V 4G2,5 | AN28: 32 | AO28: 11.1
B29: -F33 | C29: Sealing air fan 2 | D29: 4 FGR 160 MO | E29: [4 FGR 160 MO] SEALING AIR FAN RIGHT | F29: VENTILATEUR D'AIR D'ÉTANCHÉITÉ DROIT | G29: Primary air system | H29: 3Ph | I29: 400 | J29: 0.9 | K29: 0.9 | L29: 25 | M29: =ROUND(J29/(1.73*0.4),2) -> 1.3 | N29: 100 | O29: =M29*(N29/100) -> 1.3 | T29: 3RV2021-1DA10 | U29: 2.2 - 3.2 A | V29: SIE.3RV2901-1E 3RV2901-1A | W29: 3RT2015-1AP02 (1NC) | X29: 3RT2916-1CD00 3RH2911-1HA31 | Y29: GV2P08 GVAE11 (NC+NO) GVAD0110 (NC fault + NO) | Z29: 2.5 - 4 A | AA29: LC1D12P7 (1NO+1NC) LADN31 (3NO+1NC) LAD4RCU (RC) | AD29: 47506015 | AH29: A9F74202 | AI29: A9F74202 | AJ29: RXM4AB2E7 RXZE2S114M RXM021BN | AK29: LZS:PT5A5T30 LZS:PTMU0730 | AL29: XPSBAC34AP | AM29: U1000R2V 4G2,5 | AN29: 32 | AO29: 11.1
B30: -F34 | C30: Cooling fan 3 | D30: 4 FGR 492 ZV | E30: [4 FGR 492 ZV] COOLING FAN 3 | F30: VENTILATEUR DE REFROIDISSEMENT 3 | G30: Hydraulic cylinder | H30: 3Ph | I30: 400 | J30: 0.8 | K30: 0.8 | L30: 25 | M30: =ROUND(J30/(1.73*0.4),2) -> 1.16 | N30: 100 | O30: =M30*(N30/100) -> 1.16 | T30: 3RV2021-1CA10 | U30: 1.8 - 2.5 A | V30: SIE.3RV2901-1E 3RV2901-1A | W30: 3RT2015-1AP02 (1NC) | X30: 3RT2916-1CD00 3RH2911-1HA31 | Y30: GV2P08 GVAE11 (NC+NO) GVAD0110 (NC fault + NO) | Z30: 2.5 - 4 A | AA30: LC1D12P7 (1NO+1NC) LADN31 (3NO+1NC) LAD4RCU (RC) | AD30: 47506015 | AH30: A9F74202 | AI30: A9F74202 | AJ30: RXM4AB2E7 RXZE2S114M RXM021BN | AK30: LZS:PT5A5T30 LZS:PTMU0730 | AL30: XPSBAC34AP | AM30: U1000R2V 4G2,5 | AN30: 32 | AO30: 11.1
B31: -F35 | C31: SPARE (prazni prostor) | E31: SPARE (prazni prostor)
B32: -F36 | C32: SPARE (prazni prostor) | E32: SPARE (prazni prostor)
B33: ORMAR 5 - VFD 2100+200x2000x600 | D33: =4LKF001AR+4LKF005AR | J33: =SUM(J34:J37) -> 148 | K33: =SUM(K34:K37) -> 148 | M33: =SUM(M34:M37)+(SUM(M34:M37)*0.3) -> 278.044 | O33: =SUM(O34:P37)+(SUM(O34:P37)*0.3) -> 139.022 | Q33: SE.C10F3TM100
B34: -F51 | D34: 4 EBA 014 PO | E34: [4 EBA 014 PO] CONDENSATE PUMP 1 | F34: CONDENSATE PUMP 1 ALIMENTATION PRINCIPALE | G34: frekventni | H34: 3Ph | I34: 400 | J34: 37 | K34: 37 | L34: 36 | M34: =ROUND(J34/(1.73*0.4),2) -> 53.47 | N34: 100 | O34: =M34*(N34/100) -> 53.47 | P34: NSX 63A | Q34: C10F3TM063 + LV429515 + LV429515 | R34: 100A PREKIDAČ | Y34: ☑ | AD34: 47506050 | AM34: NYCWY 3x35/16 2XSLCYK-JB 3x25+3*4
B35: -F52 | D35: 4 CRE 189 MO | E35: [4 CRE 189 MO] COOLING WATER PUMP 1 | F35: POMPE EAU DE REFROIDISSEMENT 1 ALIMENTATION PRINCIPALE | G35: frekventni | H35: 3Ph | I35: 400 | J35: 37 | K35: 37 | L35: 36 | M35: =ROUND(J35/(1.73*0.4),2) -> 53.47 | N35: 100 | O35: =M35*(N35/100) -> 53.47 | P35: NSX 63A | Q35: C10F3TM063 + LV429515 + LV429515 | R35: 100A PREKIDAČ | Y35: ☑ | AD35: 47506050 | AM35: NYCWY 3x35/16 2XSLCYK-JB 3x25+3*4
B36: -F53 | D36: 4 EBA 043 PO | E36: [4 EBA 043 PO] CONDENSATE PUMP 2 | F36: CONDENSATE PUMP 2 ALIMENTATION PRINCIPALE | G36: frekventni | H36: 3Ph | I36: 400 | J36: 37 | K36: 37 | L36: 36 | M36: =ROUND(J36/(1.73*0.4),2) -> 53.47 | N36: 0 | P36: NSX 63A | Q36: C10F3TM063 + LV429515 + LV429515 | R36: 100A PREKIDAČ | Y36: ☑ | AD36: 47506050 | AM36: NYCWY 3x35/16 2XSLCYK-JB 3x25+3*4
B37: -F54 | D37: 4 CRE 196 MO | E37: [4 CRE 196 MO] COOLING WATER PUMP 2 | F37: COOLING WATER PUMP 2 ALIMENTATION PRINCIPALE | G37: frekventni | H37: 3Ph | I37: 400 | J37: 37 | K37: 37 | L37: 36 | M37: =ROUND(J37/(1.73*0.4),2) -> 53.47 | N37: 0 | P37: NSX 63A | Q37: C10F3TM063 + LV429515 + LV429515 | R37: 100A PREKIDAČ | Y37: ☑ | AD37: 47506050 | AM37: NYCWY 3x35/16 2XSLCYK-JB 3x25+3*4
B38: ORMAR 6 - VFD 2100+200x1600x600 ORMAR PRESELJEN S MCC NORMALA | D38: =4LKF001AR+4LKF006AR BIO JE:=4LKD001AR+4LKD007AR | J38: =SUM(J39:J44) -> 44 | K38: =SUM(K39:K44) -> 11 | M38: =SUM(M39:M44)+(SUM(M39:M44)*0.3) -> 82.68 | O38: =SUM(O39:P44)+(SUM(O39:P44)*0.3) -> 31.005 | P38: 3VA1032-3ED32-0AA0 - 32A 3VA9988-0AA12 AUX 1CO 3VA9157-0EK11 Rotary 3VA9152-0WA00 phase barrier -> 2 kom 3VA9111-0WD30 mala zaštita odozgora 3VA9113-0JF60 distri odozdola i izolacija | Q38: C10F3TM032 + LV429337T + LVS04033 +LV429515
B39: -F61 - ZAMJENA iz Normala | D39: 4SDX 001PO BIO JE: [4 SEO 209 PO] WASTE WATER PUMP 1 | E39: [4 SDX 001 PO] FAST FILING PUMP | F39: POMPE DE REMPLISSAGE RAPIDE | G39: Thermal water treatment | H39: 3Ph | I39: 400 | J39: 11 | K39: AŽURIRAJ samo naziv potrošača | L39: 5 | M39: =ROUND(J39/(1.73*0.4),2) -> 15.9 | N39: 0 | O39: =M39*(N39/100) -> 0 | P39: NSX 50A | Q39: C10F3TM050 + LV429515 + LV429515 | Z39: ☑ | AF39: 47506030 | AM39: NYCWY 3x6/6
B40: -F61 - ZAMJENA | D40: 4 CTE 063 PO BILO JE: [4 SEO 264 PO] WASTE WATER BOTTOM ASH PIT DISCHARG PUMP 1 | E40: [4 CTE 063 PO] COOLING WATER PUMP 1 | F40: POMPE A EAU DE REFROIDISSEMENT 1 | G40: Cooling water | H40: 3Ph | I40: 400 | J40: 5.5 | K40: AŽURIRAJ preimenuj | L40: 25 | M40: =ROUND(J40/(1.73*0.4),2) -> 7.95 | N40: 100 | O40: =M40*(N40/100) -> 7.95 | P40: NSX 32A | Q40: C10F3TM032 + LV429515 + LV429515 | Z40: ☑ | AF40: 47506015
...

Sheet Stopice i uvodnice
A1: MCC Normal | B1: promjer | C1: količina kabela | D1: Uvodnica Jacob metalna | E1: količina uvodnica | F1: Stopice | G1: količina stopica | H1: količina stopica | J1: Napomena
A2: U1000R2V 4G2,5 | B2: 11.1 | C2: =COUNTIF('Boiler MCC distribution'!$AN3:$AN55,A2) -> 26 | D2: =IF(AND(B2>=3,B2<=6),"M12", IF(AND(B2>9,B2<=13),"M20", IF(AND(B2>11,B2<=16),"M25", IF(AND(B2>14,B2<=20),"M32", IF(AND(B2>19,B2<=27),"M40", IF(AND(B2>24,B2<=35),"M50", IF(AND(B2>32,B2<=42),"M63", "-"))))))) -> M20 | E2: =C2 -> 26 | F2: stopica 2,5mm2 | G2: =C2*4 -> 104 | J2: 2 uvodnice po motoru
A3: U1000R2V 4G6 | B3: 14.3 | C3: =COUNTIF('Boiler MCC distribution'!$AN4:$AN56,A3) -> 1 | D3: =IF(AND(B3>=3,B3<=6),"M12", IF(AND(B3>9,B3<=13),"M20", IF(AND(B3>11,B3<=16),"M25", IF(AND(B3>14,B3<=20),"M32", IF(AND(B3>19,B3<=27),"M40", IF(AND(B3>24,B3<=35),"M50", IF(AND(B3>32,B3<=42),"M63", "-"))))))) -> M25 | E3: =C3 -> 1 | F3: KSB-C 6/6 | G3: =C3*4 -> 4
A4: U1000R2V 4G25 | B4: 22.8 | C4: =COUNTIF('Boiler MCC distribution'!$AN5:$AN57,A4) -> 1 | D4: =IF(AND(B4>=3,B4<=6),"M12", IF(AND(B4>9,B4<=13),"M20", IF(AND(B4>11,B4<=16),"M25", IF(AND(B4>14,B4<=20),"M32", IF(AND(B4>19,B4<=27),"M40", IF(AND(B4>24,B4<=35),"M50", IF(AND(B4>32,B4<=42),"M63", "-"))))))) -> M40 | E4: =C4 -> 1 | F4: KSB-C 25/6 | G4: =C4*4 -> 4
A7: MCC Emergency
A8: U1000R2V 4G2,5 | B8: 11.1 | C8: =COUNTIF('Emerg Boiler MCC distribution'!$AM3:$AM44,A8) -> 12 | D8: =IF(AND(B8>=3,B8<=6),"M12", IF(AND(B8>9,B8<=13),"M20", IF(AND(B8>11,B8<=16),"M25", IF(AND(B8>14,B8<=20),"M32", IF(AND(B8>19,B8<=27),"M40", IF(AND(B8>24,B8<=35),"M50", IF(AND(B8>32,B8<=42),"M63", "-"))))))) -> M20 | E8: =C8 -> 12 | F8: stopica 2,5mm2 | G8: =C8*4 -> 48
A9: U1000R2V 4G6 | B9: 14.3 | C9: =COUNTIF('Emerg Boiler MCC distribution'!$AM4:$AM45,A9) -> 1 | D9: =IF(AND(B9>=3,B9<=6),"M12", IF(AND(B9>9,B9<=13),"M20", IF(AND(B9>11,B9<=16),"M25", IF(AND(B9>14,B9<=20),"M32", IF(AND(B9>19,B9<=27),"M40", IF(AND(B9>24,B9<=35),"M50", IF(AND(B9>32,B9<=42),"M63", "-"))))))) -> M25 | E9: =C9 -> 1 | F9: KSB-C 6/6 | G9: =C9*4 -> 4
A10: U1000R2V 4G4 | B10: 12.3 | C10: =COUNTIF('Emerg Boiler MCC distribution'!$AM5:$AM46,A10) -> 2 | D10: =IF(AND(B10>=3,B10<=6),"M12", IF(AND(B10>9,B10<=13),"M20", IF(AND(B10>11,B10<=16),"M25", IF(AND(B10>14,B10<=20),"M32", IF(AND(B10>19,B10<=27),"M40", IF(AND(B10>24,B10<=35),"M50", IF(AND(B10>32,B10<=42),"M63", "-"))))))) -> M20 | E10: =C10 -> 2 | F10: stopica 4mm2 | G10: =C10*4 -> 8
A11: NYCWY 3x35/16 | B11: 32.1 | C11: =COUNTIF('Emerg Boiler MCC distribution'!$AM6:$AM47,A11) -> 0 | D11: =IF(AND(B11>=3,B11<=6),"M12", IF(AND(B11>9,B11<=13),"M20", IF(AND(B11>11,B11<=16),"M25", IF(AND(B11>14,B11<=20),"M32", IF(AND(B11>19,B11<=27),"M40", IF(AND(B11>24,B11<=35),"M50", IF(AND(B11>32,B11<=42),"M63", "-"))))))) -> M50 | E11: =C11 -> 0 | F11: KSB-C 16/6 | G11: =C11*4 -> 0 | J11: NYCWY 3x35/16 -> 2XSL(St)CYK-J 4G50 (3x50/25)
A12: NYCWY 3x6/6 | B12: 15.6 | C12: =COUNTIF('Emerg Boiler MCC distribution'!$AM7:$AM48,A12) -> 5 | D12: =IF(AND(B12>=3,B12<=6),"M12", IF(AND(B12>9,B12<=13),"M20", IF(AND(B12>11,B12<=16),"M25", IF(AND(B12>14,B12<=20),"M32", IF(AND(B12>19,B12<=27),"M40", IF(AND(B12>24,B12<=35),"M50", IF(AND(B12>32,B12<=42),"M63", "-"))))))) -> M25 | E12: =C12 -> 5 | F12: KSB-C 6/6 | G12: =C12*4 -> 20 | J12: NYCWY 3x6/6 -> 2XSL(St)CYK-J 4G6 (3x6/6)
A14: Ukupno
D15: M20 | E15: =SUMIF($D$2:$D$10,D15,$E$2:$E$10) -> 40
D16: M25 | E16: =SUMIF($D$2:$D$10,D16,$E$2:$E$10) -> 2
D17: M40 | E17: =SUMIF($D$2:$D$10,D17,$E$2:$E$10) -> 1
A20: Signali - NORD - reducir uvodnica
A21: U1000R2V 5G1,5 | B21: 10.7 | C21: 19 | D21: =IF(AND(B21>=3,B21<=6),"M12", IF(AND(B21>9,B21<=13),"M20", IF(AND(B21>11,B21<=16),"M25", IF(AND(B21>14,B21<=20),"M32", IF(AND(B21>19,B21<=27),"M40", IF(AND(B21>24,B21<=35),"M50", IF(AND(B21>32,B21<=42),"M63", "-"))))))) -> M20 | E21: 19 | F21: mala stopica | G21: =C21*4 -> 76 | J21: ide u bananu, nije potrebna uvodnica
D23: M32->M20
A26: Naručiti | B26: Narudžbeni broj | C26: Količina | D26: Spare | E26: Ukupno
A27: M32 | B27: 50.632 M | C27: =SUM(E16) -> 2 | D27: 20 | E27: =C27+C27*(D27/100) -> 2.4 | F27: 14-20mm
A28: M32x1,5 - reducir | B28: 50.632 M/R | C28: =SUM(E15:E16) -> 42 | D28: 30 | E28: =C28+C28*(D28/100) -> 54.6 | F28: 12-20mm
A29: M40 | B29: 50.640 M | C29: =E17 -> 1 | D29: 50 | E29: =C29+C29*(D29/100) -> 1.5
A30: stopica 2,5mm2 | C30: =SUMIF($F$2:$F$10,A30,$G$2:$G$10) -> 152 | D30: 20 | E30: =C30+C30*(D30/100) -> 182.4
A31: stopica 4mm2 | C31: =SUMIF($F$2:$F$10,A31,$G$2:$G$10) -> 8 | D31: 20 | E31: =C31+C31*(D31/100) -> 9.6
A32: KSB-C 6/6 | B32: MP 102 002 | C32: =SUMIF($F$2:$F$10,A32,$G$2:$G$10) -> 8 | D32: 20 | E32: =C32+C32*(D32/100) -> 9.6
A33: KSB-C 25/6 | B33: MP 102 016 | C33: =SUMIF($F$2:$F$10,A33,$G$2:$G$10) -> 4 | D33: 20 | E33: =C33+C33*(D33/100) -> 4.8
A41: Motor koji koristimo | B41: Uvodnica | C41: Stopica
A42: NORD SK3282ABGH-100LP/4 TF -> 100 frame | B42: M32 x2 | C42: M6 | D42: https://nordgearmotors.com/nord-clincher-catalog/#SK3282

Sheet Stopice i uvodnice_rev2
A1: MCC Normal | B1: promjer | C1: količina kabela | D1: Uvodnica Jacob metalna | E1: količina uvodnica | F1: Stopice | G1: količina stopica | H1: količina stopica | J1: Napomena
A2: U1000R2V 4G2,5 | B2: 11.1 | C2: =COUNTIF('Boiler MCC distribution'!$AN3:$AN55,A2) -> 26 | D2: =IF(AND(B2>=3,B2<=6),"M12", IF(AND(B2>9,B2<=13),"M20", IF(AND(B2>11,B2<=16),"M25", IF(AND(B2>14,B2<=20),"M32", IF(AND(B2>19,B2<=27),"M40", IF(AND(B2>24,B2<=35),"M50", IF(AND(B2>32,B2<=42),"M63", "-"))))))) -> M20 | E2: =C2 -> 26 | F2: stopica 2,5mm2 | G2: =C2*4 -> 104 | J2: 2 uvodnice po motoru
A3: U1000R2V 4G6 | B3: 14.3 | C3: =COUNTIF('Boiler MCC distribution'!$AN4:$AN56,A3) -> 1 | D3: =IF(AND(B3>=3,B3<=6),"M12", IF(AND(B3>9,B3<=13),"M20", IF(AND(B3>11,B3<=16),"M25", IF(AND(B3>14,B3<=20),"M32", IF(AND(B3>19,B3<=27),"M40", IF(AND(B3>24,B3<=35),"M50", IF(AND(B3>32,B3<=42),"M63", "-"))))))) -> M25 | E3: =C3 -> 1 | F3: KSB-C 6/6 | G3: =C3*4 -> 4
A4: U1000R2V 4G25 | B4: 22.8 | C4: =COUNTIF('Boiler MCC distribution'!$AN5:$AN57,A4) -> 1 | D4: =IF(AND(B4>=3,B4<=6),"M12", IF(AND(B4>9,B4<=13),"M20", IF(AND(B4>11,B4<=16),"M25", IF(AND(B4>14,B4<=20),"M32", IF(AND(B4>19,B4<=27),"M40", IF(AND(B4>24,B4<=35),"M50", IF(AND(B4>32,B4<=42),"M63", "-"))))))) -> M40 | E4: =C4 -> 1 | F4: KSB-C 25/6 | G4: =C4*4 -> 4
A7: MCC Emergency
A8: U1000R2V 4G2,5 | B8: 11.1 | C8: =COUNTIF('Emerg Boiler MCC distribution'!$AM3:$AM44,A8) -> 12 | D8: =IF(AND(B8>=3,B8<=6),"M12", IF(AND(B8>9,B8<=13),"M20", IF(AND(B8>11,B8<=16),"M25", IF(AND(B8>14,B8<=20),"M32", IF(AND(B8>19,B8<=27),"M40", IF(AND(B8>24,B8<=35),"M50", IF(AND(B8>32,B8<=42),"M63", "-"))))))) -> M20 | E8: =C8 -> 12 | F8: stopica 2,5mm2 | G8: =C8*4 -> 48
A9: U1000R2V 4G6 | B9: 14.3 | C9: =COUNTIF('Emerg Boiler MCC distribution'!$AM4:$AM45,A9) -> 1 | D9: =IF(AND(B9>=3,B9<=6),"M12", IF(AND(B9>9,B9<=13),"M20", IF(AND(B9>11,B9<=16),"M25", IF(AND(B9>14,B9<=20),"M32", IF(AND(B9>19,B9<=27),"M40", IF(AND(B9>24,B9<=35),"M50", IF(AND(B9>32,B9<=42),"M63", "-"))))))) -> M25 | E9: =C9 -> 1 | F9: KSB-C 6/6 | G9: =C9*4 -> 4
A10: U1000R2V 4G4 | B10: 12.3 | C10: =COUNTIF('Emerg Boiler MCC distribution'!$AM5:$AM46,A10) -> 2 | D10: =IF(AND(B10>=3,B10<=6),"M12", IF(AND(B10>9,B10<=13),"M20", IF(AND(B10>11,B10<=16),"M25", IF(AND(B10>14,B10<=20),"M32", IF(AND(B10>19,B10<=27),"M40", IF(AND(B10>24,B10<=35),"M50", IF(AND(B10>32,B10<=42),"M63", "-"))))))) -> M20 | E10: =C10 -> 2 | F10: stopica 4mm2 | G10: =C10*4 -> 8
A11: NYCWY 3x35/16 | B11: 32.1 | C11: =COUNTIF('Emerg Boiler MCC distribution'!$AM6:$AM47,A11) -> 0 | D11: =IF(AND(B11>=3,B11<=6),"M12", IF(AND(B11>9,B11<=13),"M20", IF(AND(B11>11,B11<=16),"M25", IF(AND(B11>14,B11<=20),"M32", IF(AND(B11>19,B11<=27),"M40", IF(AND(B11>24,B11<=35),"M50", IF(AND(B11>32,B11<=42),"M63", "-"))))))) -> M50 | E11: =C11 -> 0 | F11: KSB-C 16/6 | G11: =C11*4 -> 0 | J11: NYCWY 3x35/16 -> 2XSL(St)CYK-J 4G50 (3x50/25)
A12: NYCWY 3x6/6 | B12: 15.6 | C12: =COUNTIF('Emerg Boiler MCC distribution'!$AM7:$AM48,A12) -> 5 | D12: =IF(AND(B12>=3,B12<=6),"M12", IF(AND(B12>9,B12<=13),"M20", IF(AND(B12>11,B12<=16),"M25", IF(AND(B12>14,B12<=20),"M32", IF(AND(B12>19,B12<=27),"M40", IF(AND(B12>24,B12<=35),"M50", IF(AND(B12>32,B12<=42),"M63", "-"))))))) -> M25 | E12: =C12 -> 5 | F12: KSB-C 6/6 | G12: =C12*4 -> 20 | J12: NYCWY 3x6/6 -> 2XSL(St)CYK-J 4G6 (3x6/6)
A14: Ukupno
D15: M20 | E15: =SUMIF($D$2:$D$10,D15,$E$2:$E$10) -> 40
D16: M25 | E16: =SUMIF($D$2:$D$10,D16,$E$2:$E$10) -> 2
D17: M40 | E17: =SUMIF($D$2:$D$10,D17,$E$2:$E$10) -> 1
A20: Signali - NORD - reducir uvodnica
A21: U1000R2V 5G1,5 | B21: 10.7 | C21: 19 | D21: =IF(AND(B21>=3,B21<=6),"M12", IF(AND(B21>9,B21<=13),"M20", IF(AND(B21>11,B21<=16),"M25", IF(AND(B21>14,B21<=20),"M32", IF(AND(B21>19,B21<=27),"M40", IF(AND(B21>24,B21<=35),"M50", IF(AND(B21>32,B21<=42),"M63", "-"))))))) -> M20 | E21: 19 | F21: mala stopica | G21: =C21*4 -> 76 | J21: ide u bananu, nije potrebna uvodnica
D23: M32->M20
A26: Naručiti | B26: Narudžbeni broj | C26: Količina | D26: Spare | E26: Ukupno
A27: M32 | B27: 50.632 M | C27: =SUM(E16) -> 2 | D27: 20 | E27: =C27+C27*(D27/100) -> 2.4 | F27: 14-20mm
A28: M25 | C28: =SUM(E15:E16) -> 42 | D28: 20 | E28: =C28+C28*(D28/100) -> 50.4 | F28: 11-16mm
A29: REDUC-M-KV-M32/M25 | B29: 1647637 | E29: =E28 -> 50.4
A30: M40 | B30: 50.640 M | C30: =E17 -> 1 | D30: 50 | E30: =C30+C30*(D30/100) -> 1.5
A31: stopica 2,5mm2 | C31: =SUMIF($F$2:$F$10,A31,$G$2:$G$10) -> 152 | D31: 20 | E31: =C31+C31*(D31/100) -> 182.4
A32: stopica 4mm2 | C32: =SUMIF($F$2:$F$10,A32,$G$2:$G$10) -> 8 | D32: 20 | E32: =C32+C32*(D32/100) -> 9.6
A33: KSB-C 6/6 | B33: MP 102 002 | C33: =SUMIF($F$2:$F$10,A33,$G$2:$G$10) -> 8 | D33: 20 | E33: =C33+C33*(D33/100) -> 9.6
A34: KSB-C 25/6 | B34: MP 102 016 | C34: =SUMIF($F$2:$F$10,A34,$G$2:$G$10) -> 4 | D34: 20 | E34: =C34+C34*(D34/100) -> 4.8
A42: Motor koji koristimo | B42: Uvodnica | C42: Stopica
A43: NORD SK3282ABGH-100LP/4 TF -> 100 frame | B43: M32 x2 | C43: M6 | D43: https://nordgearmotors.com/nord-clincher-catalog/#SK3282
